Workbook
Name a.1: #REF!
Name a.1: #REF!
Name a.1: #REF!
Name a.1: #REF!
Name a.1: #REF!
Name a.1: #REF!
Name a.1: #REF!
Name a.1: #REF!
Name a.1: #REF!
Name pr.1: #REF!
Name pr.1: #REF!
Name pr.1: #REF!
Name pr.1: #REF!
Name pr.1: #REF!
Name pr.1: #REF!
Name pr.1: #REF!
Name pr.1: #REF!
Name pr.1: #REF!
Name pr.11: #REF!
Name pr.11: #REF!
Name pr.11: #REF!
Name pr.11: #REF!
Name pr.11: #REF!
Name pr.11: #REF!
Name pr.11: #REF!
Name pr.11: #REF!
Name pr.11: #REF!
Name pr.2: #REF!
Name pr.2: #REF!
Name pr.2: #REF!
Name pr.2: #REF!
Name pr.2: #REF!
Name pr.2: #REF!
Name pr.2: #REF!
Name pr.2: #REF!
Name pr.2: #REF!
Name pr.21: #REF!
Name pr.21: #REF!
Name pr.21: #REF!
Name pr.21: #REF!
Name pr.21: #REF!
Name pr.21: #REF!
Name pr.21: #REF!
Name pr.21: #REF!
Name pr.21: #REF!
Name pr.21a: #REF!
Name pr.21a: #REF!
Name pr.21a: #REF!
Name pr.21a: #REF!
Name pr.21a: #REF!
Name pr.21a: #REF!
Name pr.21a: #REF!
Name pr.21a: #REF!
Name pr.21a: #REF!
Name pr.3: #REF!
Name pr.3: #REF!
Name pr.3: #REF!
Name pr.3: #REF!
Name pr.3: #REF!
Name pr.3: #REF!

Sheet 60-20moin
F1: موجودی نقد و بانک | K1: اسناد دریافتنی تجاری | L1: حسابهای دریافتنی تجاری | N1: حسابها و اسناد دریافتنی غیر تجاری | T1: سپرده و پیش پرداختها | U1: سپرده و پیش پرداختها | AC1: دارائیهای ثابت مشهود | AM1: دارائیهای نامشهود | AP1: سرمایه گذاریهای بلند مدت | AQ1: سایر دارائیها | AU1: اسناد پرداختنی تجاری | AV1: اسناد پرداختنی تجاری | AX1: حسابهای پرداختنی تجاری | BY1: ذخیره مالیات | BZ1: سود سهام پرداختنی | CA1: تسهیلات مالی دریافتی | CB1: تسهیلات مالی دریافتی | CC1: تسهیلات مالی دریافتی | CD1: ذخیره مزایای پایان خدمت کارکنان | CF1: سرمایه | CG1: اندوخته ها | CI1: سود (زیان) انباشته | CJ1: سود (زیان) جاری | CN1: هزینه های توزیع و فروش | EL1: هزینه مالی | FA1: سایر درآمدها و(هزینه های) عملیاتی
F2: 146061763873 | K2: 696176795595 | L2: 1085623835217 | N2: 6189565588 | T2: 7843473671 | U2: 7843473671 | AC2: 1.2225803e+11 | AM2: 4206214756 | AP2: 3738354260 | AQ2: 3854274049 | AU2: 0 | AV2: 0 | AX2: 0 | BY2: 0 | BZ2: 0 | CA2: 0 | CB2: 0 | CC2: 0 | CD2: 0 | CF2: 0 | CG2: 0 | CI2: 0 | CJ2: 0 | CN2: 23541017883 | EL2: 7450842054 | FA2: 0
F3: 0 | K3: 0 | L3: 0 | N3: 0 | T3: 0 | U3: 0 | AC3: 0 | AM3: 0 | AP3: 0 | AQ3: 0 | AU3: -283542299159 | AV3: -283542299159 | AX3: -1984940580150 | BY3: -195967152 | BZ3: -135000043320 | CA3: -43698630137 | CB3: -43698630137 | CC3: -43698630137 | CD3: -51030832648 | CF3: -50000000000 | CG3: -5000000000 | CI3: -26386619115 | CJ3: 0 | EL3: 0 | FA3: 0
C4: کـــــاربرگ طبقه بندی
C5: نام حساب | D5: تراز معین | F5: موجودی نقد و بانک | J5: سرمایه گذاری کوتاه مدت | K5: حسابها و اسناد دریافتنی تجاری | N5: حسابها و اسناد دریافتنی غیر تجاری | Q5: موجودی کالا | T5: سپرده و پیش پرداختها | U5: سپرده و پیش پرداختها | AB5: جاری شرکا | AC5: دارائیهای ثابت مشهود | AM5: دارائیهای نامشهود | AP5: دریافتنی بلند مدت | AQ5: سایر دارائیها | AU5: حسابها واسناد پرداختنی تجاری | AY5: حسابها واسناد پرداختنی غیر تجاری | AZ5: حسابها واسناد پرداختنی غیر تجاری | BA5: حسابها واسناد پرداختنی غیر تجاری | BB5: حسابها واسناد پرداختنی غیر تجاری | BC5: حسابها واسناد پرداختنی غیر تجاری | BD5: حسابها واسناد پرداختنی غیر تجاری | BW5: پرداختنی های بلند مدت | BY5: ذخیره مالیات | BZ5: سود سهام پرداختنی | CA5: تسهیلات مالی دریافتی | CD5: ذخیره مزایای پایان خدمت | CE5: ذخایر | CF5: سرمایه | CG5: اندوخته ها | CI5: سود (زیان) انباشته | CJ5: سود (زیان) جاری | CL5: فروش | CM5: بهای تمام شده | CN5: هزینه های پرسنلی | CY5: اسنهلاک | DA5: هزینه های عمومی و توزیع و فروش | EB5: سایر درآمدها و(هزینه های) عملیاتی | EL5: هزینه مالی | EP5: سایر درآمدها و(هزینه های) غیر عملیاتی | FA5: جمع
F6: 101 | G6: 102 | H6: 103 | I6: 104 | J6: 110 | K6: 120 | L6: 121 | N6: 140 | O6: 141 | P6: 142 | Q6: 150 | R6: 151 | S6: 152 | T6: 160 | U6: 160 | Y6: 161 | Z6: 161 | AA6: 162 | AC6: 200 | AD6: 203 | AE6: 201 | AF6: 202 | AG6: 204 | AH6: 204 | AK6: 204 | AL6: 205 | AM6: 250 | AN6: 251 | AO6: 252 | AP6: 260 | AQ6: 270 | AR6: 271 | AU6: 300 | AV6: 300 | AW6: 301 | AX6: 302 | AY6: 333 | AZ6: 334 | BA6: 335 | BB6: 336 | BC6: 337 | BD6: 338 | BE6: 339 | BF6: 3316 | BG6: 3310 | BH6: 3311 | BI6: 3312 | BJ6: 3313 | BK6: 3314 | BL6: 3319 | BU6: 3317 | BV6: 3315 | BX6: 337 | BY6: 350 | BZ6: 360 | CA6: 380 | CB6: 380 | CC6: 380 | CD6: 420 | CF6: 450 | CG6: 460 | CI6: 470 | CJ6: 480 | CL6: 500 | CM6: 600 | CN6: 700 | CO6: 701 | CP6: 701 | CQ6: 702 | CR6: 703 | CS6: 704 | CT6: 705 | CU6: 705 | CV6: 717 | CY6: 730 | DA6: 710 | DB6: 711 | DE6: 712 | DI6: 713 | DK6: 714 | DR6: 715 | DU6: 716 | DX6: 717 | EA6: 718 | EB6: 800 | EI6: 801 | EJ6: 802 | EK6: 803 | EL6: 740 | EM6: 351 | EN6: 351 | EO6: 850 | EP6: 850 | ER6: 851 | ES6: 852 | ET6: 853 | EU6: 854 | EV6: 854 | EX6: 854 | EY6: 854 | EZ6: 855
F7: موجودي نزد بانكها | G7: وجوه در راه | H7: موجودي صندوق | I7: تنخواه گردانها | J7: سرمایه گذاری کوتاه مدت | K7: حسابهای دریافتنی تجاری | L7: اسناد دریافتنی تجاری | M7: اوراق دریافتنی کوتاه مدت | N7: بدهي كاركنان (وام و جاري و بیمه عمر) | O7: وزارت دارایی-مالیات و عوارض ارزش افزوده | P7: سايراشخاص | Q7: موجودی کالا | R7: موجودی کالای امانی | S7: سایر موجودیها | T7: بيمه موجودی کالا و داراييهای ثابت | U7: ودیعه اجاره محل | V7: پیش پرداخت بیمه مسئولیت مدنی و تکمیلی | W7: پیش پرداخت تامین کنندگان | X7: پیش پرداخت مالیات | Y7: خرید کالا | Z7: سازمان حسابرسی | AA7: ساير | AB7: جاری شرکا | AC7: دارائیهای ثابت مشهود | AD7: دارایی های در جریان تکمیل | AE7: اصلاح انبار بندر عباس | AF7: اصلاح ساختمان اداری و درب و نرده های مرکز اهواز | AG7: احداث انبار و سیستم اطفاء و اعلام حریق و سیتم گرمایشی مرکز تبریز | AH7: اجرای سیستم دوربین مدار بسته (تهران یک، ساری،یزد،گرگان،کرمانشاهو ارومیه ) | AI7: احداث مرکز اردبیل | AJ7: پروژه مرکز همدان(اعلام حریق و اطفاء حریق ) | AK7: پروژه تهران یک | AL7: سایر | AM7: حق الامتياز تلفن , برق و غيره | AN7: نرم افزارهای کامپیوتر | AO7: زمينهاي موقوفي | AP7: اوراق اخزا | AQ7: حصه بلند مدت وام كاركنان | AR7: حصه بلند مدت اسناد دريافتني تجاری | AS7: سپرده نزد بانکها | AT7: دارائی مالیات انتقالی | AU7: اسناد پرداختني تجاري --شرکتهای گروه | AV7: اسناد پرداختني تجاري -تامین کنندگان | AW7: حسابهای پرداختني تجاري -شرکتهای گروه | AX7: حسابهای پرداختني تجاري تامین کنندگان | AY7: ساير اشخاص | AZ7: جاری سهامداران | BA7: ذخيره بازخرید مرخصی | BB7: اسناد پرداختنی غیرتجاری | BC7: مطالبات معوقه کارکنان مستعفی | BD7: ذخيره هزينه هاي تعلق گرفته پرداخت نشده | BE7: سپرده بیمه | BF7: حقوق پرداختنی | BG7: حق بيمه پرداختني | BH7: مالیات حقوق پرداختنی | BI7: واریزیهای نامشخص | BJ7: سپرده حسن انجام كار | BK7: ماليات تكليفي پرداختني | BL7: بستانکاران مشتریان | BM7: سپرده های پرداختنی | BN7: وزارت دارایی مالیات و عوارض | BO7: وزارت دارایی مالیات تکلیفی و حقوق | BP7: تامین اجتماعی -حق بیمه پرداختنی سایر | BQ7: تامین اجتماعی -حقوق کارکان | BR7: وزارت دارایی مالیات اجاره | BS7: بستانکاران کارکنان | BT7: اسناد پرداختنی یرتجاری | BU7: بستانکاران غیرتجاری | BV7: ساير | BW7: حسابها و اسناد پرداختنی بلند مدت | BX7: پیش دریافتها | BY7: ذخیره مالیات | BZ7: سود سهام پرداختنی | CA7: تسهیلات مالی دریافتی | CB7: سود و کارمزد سالجاری | CC7: سود و کارمزد سال آتی | CD7: ذخیره مزایای پایان خدمت | CE7: ذخیره کاهش ارزش سرمایه گذاری | CF7: سرمایه | CG7: اندوخته ها | CH7: سود (زیان) سنواتی | CI7: سود (زیان) انباشته | CJ7: سود (زیان) جاری | CK7: مازاد تجدید ارزیابی | CL7: فروش | CM7: بهای تمام شده | CN7: حقوق و دستمزد و مزايا | CO7: پاداش ترویج فروش | CP7: عيدي, پاداش وكارايي | CQ7: مزاياي پايان خدمت و مرخصي كاركنان | CR7: بيمه سهم كارفرما و بيمه بيكاري | CS7: اياب وذهاب, سفر وفوق العاده ماموريت | CT7: كمكهاي غير نقدي | CU7: شیر و غذا پوشاک ، آبدارخانه و پذيرايي | CV7: پاداش هیئت مدیره | CW7: استهلاك داراييهاي ثابت نامشهود | CX7: هزینه استهلاک | CY7: استهلاك داراييهاي ثابت مشهود | CZ7: استهلاك داراييهاي ثابت نا مشهود | DA7: حمل و نقل | DB7: تعمير و نگهداري ساختمان, وسائط نقليه و اثاثه | DC7: بهداشت و درمان | DD7: لوازم و ملزومات مصرفی | DE7: آب، برق, سوخت, تلفن و پست | DF7: حق حضور در جلسات هیدت مدیره | DG7: آبدارخانه و پذیرایی | DH7: سوخت وسائط نقلیه | DI7: بيمه دارایيهاي ثابت و موجودي كالا | DJ7: مالیات و عوارض سالیانه | DK7: کارمزد خدمات بانکی | DL7: اشتراک و اینترنت | DM7: هزینه سفر | DN7: هزینه اجاره | DO7: هزینه مالیات اجاره | DP7: حق الزحمه و حق المشاوره | DQ7: اجاره وسایط نقلیه | DR7: اجاره انبار | DS7: ایاب ذهاب | DT7: بیمه تکمیلی و مسئولیت | DU7: آگهی و تبليغات و بازاريابي | DV7: هزینه مالی | DW7: هزینه حسابرسی | DX7: مطالبات مشكوك الوصول | DY7: هزینه دادگاه | DZ7: حقوق و مزایای تامین نیروی انسانی | EA7: سایر | EB7: درآمد حاصل از ترویج فروش | EC7: تخفیف ریالی تامین کننده | ED7: اختلاف فی | EE7: اهدایی تامین کننده | EF7: تخفیفات نقدی | EG7: جوایز و هدایا | EH7: ضایعات کالا | EI7: جوایز جنسی | EJ7: خالص کسر و اضافی انبار | EK7: سایر | EL7: هزینه مالی | EM7: اصلاح مالیات عملکرد سال 1389 | EN7: پرداخت مالیات ارزش افزوده سال های 87 ، 91 ، 92 | EO7: مالیات عوارض ارزش افزوده سال 93 الی 95 | EP7: سود ناشي از فروش دارایيهاي ثابت مشهود | EQ7: سود و زیان ناشي از فروش دارایيهاي ثابت نامشهود | ER7: سود سپرده بانكي | ES7: جوایز و هدایا | ET7: سود وزیان ناشی از تسعیر داراییهای وبدهیهای ارزی | EU7: درآمد حاصل از فروش ضایعات غیر دارویی | EV7: خسارت دریافتی از بیمه | EW7: سود اوراق | EX7: درآمد حاصل از اجاره محل | EY7: مازاد ذخیره هزینه های بازآموزی وزارت بهداشت | EZ7: سایر
A8: کد حساب | B8: کد حساب | D8: بدهکار | E8: بستانکار | Y8: 160004 | Z8: 04-000051 | AD8: 11-000026 | AE8: 11-000022 | AF8: 11-000027 | AN8: 11-000015 | AY8: ساير | AZ8: 10-000018
A9: 100 | B9: 10001 | C9: صندوق مراکز | D9: 415714488 | E9: 0 | H9: =D9-E9 -> 415714488 | FA9: =SUM(F9:EZ9) -> 415714488 | FB9: =D9-E9-FA9 -> 0
A10: 100 | B10: 10002 | C10: تنخواه گردان | D10: 6435067913 | E10: 0 | I10: =$D10-$E10 -> 6435067913 | FA10: =SUM(F10:EZ10) -> 6435067913 | FB10: =D10-E10-FA10 -> 0
A11: 100 | B11: 10003 | C11: بانکها | D11: 295554024886 | E11: 0 | F11: =$D11-$E11 -> 295554024886 | FA11: =SUM(F11:EZ11) -> 295554024886 | FB11: =D11-E11-FA11 -> 0
A12: 100 | B12: 10004 | C12: صندوق | D12: 0 | E12: 0 | H12: =D12 -> 0 | FA12: =SUM(F12:EZ12) -> 0 | FB12: =D12-E12-FA12 -> 0
A13: 100 | B13: 10005 | C13: صندوق بانک | D13: 0 | E13: 0 | H13: =D13-E13 -> 0 | FA13: =SUM(F13:EZ13) -> 0 | FB13: =D13-E13-FA13 -> 0
A14: 100 | B14: 10006 | C14: سپرده مسدودی تسهیلات | D14: 1200000000 | E14: 0 | F14: =D14 -> 1200000000 | FA14: =SUM(F14:EZ14) -> 1200000000 | FB14: =D14-E14-FA14 -> 0
A15: 100 | B15: 10007 | C15: سایر سپرده ها | D15: 62947210684 | E15: 0 | F15: =D15 -> 62947210684 | FA15: =SUM(F15:EZ15) -> 62947210684 | FB15: =D15-E15-FA15 -> 0
A16: 110 | B16: 11001 | C16: بدهکاران تجاری | D16: 4986953097879 | E16: 0 | K16: =D16 -> 4986953097879 | L16: 0 | FA16: =SUM(F16:EZ16) -> 4986953097879 | FB16: =D16-E16-FA16 -> 0 | FD16: 875030291380
A17: 110 | B17: 11002 | C17: اسناد دریافتنی تجاری | D17: 223539913155 | E17: 0 | L17: =D17 -> 223539913155 | FA17: =SUM(F17:EZ17) -> 223539913155 | FB17: =D17-E17-FA17 -> 0 | FD17: 2881420035
A18: 110 | B18: 11003 | C18: اسناد درجریان وصول | D18: 9178000561668 | E18: 0 | L18: =D18 -> 9178000561668 | FA18: =SUM(F18:EZ18) -> 9178000561668 | FB18: =D18-E18-FA18 -> 0 | FD18: 1316583126617
A19: 120 | B19: 12002 | C19: بدهکاران اشخاص | D19: 15919913267 | E19: 0 | P19: =D19 -> 15919913267 | FA19: =SUM(F19:EZ19) -> 15919913267 | FB19: =D19-E19-FA19 -> 0 | FD19: 1894194204
A20: 120 | B20: 12003 | C20: بدهکاران کارکنان-وام | D20: 30889976248 | E20: 0 | N20: =D20 -> 30889976248 | FA20: =SUM(F20:EZ20) -> 30889976248 | FB20: =D20-E20-FA20 -> 0 | FD20: 3344630162
A21: 120 | B21: 12004 | C21: بدهکاران کارکنان-مساعده | D21: 2844479771 | E21: 0 | N21: =D21 -> 2844479771 | FA21: =SUM(F21:EZ21) -> 2844479771 | FB21: =D21-E21-FA21 -> 0 | FD21: 203634211
A22: 120 | B22: 12005 | C22: بدهکاران بانکها | E22: 0 | FA22: =SUM(F22:EZ22) -> 0 | FB22: =D22-E22-FA22 -> 0 | FD22: 34121309106
A23: 120 | B23: 12006 | C23: بدهکاران دارایی-ارزش افزوده | D23: 73486424009 | E23: 0 | FA23: =SUM(F23:EZ23) -> 0 | FB23: =D23-E23-FA23 -> 73486424009 | FD23: 13251858110
A24: 120 | B24: 12008 | C24: بدهکاران مطالبات مشکوک الوصول | D24: 11254768389 | E24: 0 | P24: 11254768389 | FA24: =SUM(F24:EZ24) -> 11254768389 | FB24: =D24-E24-FA24 -> 0 | FD24: 11254768389
A25: 120 | B25: 12010 | C25: بدهکاران کارکنان-بیمه تکمیلی | E25: 0 | BX25: 0 | FA25: =SUM(F25:EZ25) -> 0 | FB25: =D25-E25-FA25 -> 0
A26: 120 | B26: 12011 | C26: بدهکاران کارکنان -غیرتجاری | D26: 4348932786 | E26: 0 | N26: =D26 -> 4348932786 | FA26: =SUM(F26:EZ26) -> 4348932786 | FB26: =D26-E26-FA26 -> 0 | FD26: 6617770269
A27: 120 | B27: 12017 | C27: بدهکاران کارکنان-وام * | D27: 2191524667 | E27: 0 | N27: =D27 -> 2191524667 | FA27: =SUM(F27:EZ27) -> 2191524667 | FB27: =D27-E27-FA27 -> 0 | FD27: 1525331628
A28: 120 | B28: 12018 | C28: بدهکاران کارکنان-بیمه ایران نمایندگی صفری | E28: 0 | N28: =D28 -> 0 | FA28: =SUM(F28:EZ28) -> 0 | FB28: =D28-E28-FA28 -> 0 | FD28: 3431248137
A29: 120 | B29: 12019 | C29: بدهکاران تامین کنندگان امانی | E29: 0 | FA29: =SUM(F29:EZ29) -> 0 | FB29: =D29-E29-FA29 -> 0
A30: 120 | B30: 12021 | C30: بدهکاران کارکنان-وام صندوق | D30: 46774631523 | E30: 0 | N30: =D30 -> 46774631523 | FA30: =SUM(F30:EZ30) -> 46774631523 | FB30: =D30-E30-FA30 -> 0
A31: 120 | B31: 12022 | C31: بدهکاران پرسنل -صندوق | E31: 0 | N31: =D31 -> 0 | FA31: =SUM(F31:EZ31) -> 0 | FB31: =D31-E31-FA31 -> 0
A32: 120 | B32: 12023 | C32: بدهکاران کارکنان-جرائم | D32: 253932500 | E32: 0 | N32: =D32 -> 253932500 | FA32: =SUM(F32:EZ32) -> 253932500 | FB32: =D32-E32-FA32 -> 0
A33: 120 | B33: 12024 | C33: بدهکاران کارکنان-علی الحساب عیدی | D33: 398271000 | E33: 0 | N33: =D33 -> 398271000 | FA33: =SUM(F33:EZ33) -> 398271000 | FB33: =D33-E33-FA33 -> 0
A34: 120 | B34: 12025 | C34: بدهکاران کارکنان -بیمه آسیا نمایندگی عصاره | D34: 22556131233 | E34: 0 | N34: =D34 -> 22556131233 | FA34: =SUM(F34:EZ34) -> 22556131233 | FB34: =D34-E34-FA34 -> 0
A35: 120 | B35: 12026 | C35: بدهکاران کارکنان-وام تبلت | D35: 677562504 | E35: 0 | N35: =D35 -> 677562504 | FA35: =SUM(F35:EZ35) -> 677562504 | FB35: =D35-E35-FA35 -> 0
A36: 130 | B36: 13001 | C36: موجودی کالا | D36: 2092913333118 | E36: 0 | Q36: =D36 -> 2092913333118 | FA36: =SUM(F36:EZ36) -> 2092913333118 | FB36: =D36-E36-FA36 -> 0 | FD36: 1382739810400
A37: 130 | B37: 13002 | C37: موجودی کالای بین راهی | E37: 0 | Q37: =D37 -> 0 | FA37: =SUM(F37:EZ37) -> 0 | FB37: =D37-E37-FA37 -> 0
A38: 130 | B38: 13003 | C38: برگشت از خرید | E38: 0 | Q38: =E38 -> 0 | FA38: =SUM(F38:EZ38) -> 0 | FB38: =D38+E38-FA38 -> 0
A39: 130 | B39: 13004 | C39: کالای امانی ما نزد دیگران | E39: 0 | Q39: =D39 -> 0 | FA39: =SUM(F39:EZ39) -> 0 | FB39: =D39+E39-FA39 -> 0
A40: 130 | B40: 13005 | C40: تفاوت مارژین | D40: 3261673 | E40: 0 | Q40: =D40 -> 3261673 | BV40: 0 | FA40: =SUM(F40:EZ40) -> 3261673 | FB40: =D40-E40-FA40 -> 0 | FD40: 94502434
...

Sheet tax
B1: مطابقت محاسبه ماليات عملكرد در اظهارنامه و صورت های مالی
B2: شـــرح | D2: عملكرد سال مالي 1402 | F2: عملكرد سال مالي 1401
B3: سود ابرازي | D3: =سودوزيان!F17 -> -23062250215 | F3: =سودوزيان!H17 -> 364042068215 | H3: =D3-F3 -> -387104318430 | I3: =H3/F3 -> -1.0633505
B4: كسر ميشود درآمدهاي معاف :
B5: 1) درآمدحاصل از صادرات ( ماده 141 ق م م ) | D5: 0 | F5: 0
B6: 2) فعاليتهاي صنعتي اولويتهاي خاص ( ماده 132 ق م م ) | D6: 0 | F6: 0
B7: 3)در آمد حاصل از سرمايه گذاري | D7: 0 | F7: 0
B8: 4) سودحاصل ازسپرده بانكي ( ماده 145 ق م م ) | D8: 0 | F8: 0
B9: 5) درآمد حاصل ازفروش دارایی ثابت | D9: 0 | F9: 0
B10: 6) 25 درصد از درآمد حاصل از اجاره | D10: 0 | F10: 0
B11: 7) درآمد خسارت دریافتی از بیمه | D11: 0 | F11: 0
B12: 8) فعاليت هاي كشاورزي ( ماده 81 ق م م ) | D12: 0 | F12: 0
B13: 9) مازاد هزینه بازآموزی وزارت بهداشت ( مالیات پرداختی در سال 1390 ) | D13: 0 | F13: 0
B14: ساير موارد موثربردرآمد مشمول ماليات :
B15: الف ) برگشت تخفیفات نقدی | D15: 0 | F15: 0
B16: ب) برگشت اختلاف تسویه | D16: 0 | F16: 0
B17: ج) برگشت تخفیفات موردی | D17: 0 | F17: 0
B18: د)برگشت هزینه مطالبات مشکوک الوصول | D18: 0 | F18: 0
B19: ه) برگشت پاداش هیئت مدیره | D19: 0 | F19: 0
B20: و) برگشت مالیات عملکرد و حقوق هزینه شده | D20: 0 | F20: 0
B21: اصلاح مالیات عملکرد | D21: 0 | F21: 0
B22: ســود مشمول ماليات | D22: =SUM(D3:D21) -> -23062250215 | F22: 87941592383
B23: 1) 25% ماليات سود سهامداران ( ماده 105 ق م م ) تبصره 7 | D23: 0 | F23: 21985398096 | I23: =D23/F23-1 -> -1
B24: 1)3درهزارعوارض اطاق بازرگاني | D24: 0 | F24: 0
B25: 2) تخفیف در نرخ مالیات متعلقه ( ماده 105ق م م ) 1% مالیات در آمد مشمول
B26: 3) ساير عوارض | D26: 0 | F26: 0
B27: جـــمع ماليات ابرازي | D27: =SUM(D22:D26)*25% -> -5.7655626e+09 | F27: =F23 -> 21985398096
F29: =F27+'[2]P&L'!H20 -> 21985123399

Sheet کاور

Sheet ص امضا
A5: ='سر برگ صفحات'!A1 -> شرکت داروسازان التیام (سهامی خاص)
A6: صورتهاي مالي
A7: ='سر برگ صفحات'!A3 -> سال مالی منتهی به 30 اسفند 1403
A8: مجمع عمومی صاحبان سهام
A9: با احترام
A10: به پیوست صورتهای مالی شرکت داروسازان التیام (سهامی خاص) مربوط به سال مالی منتهي به 30 اسفند ماه 1403 تقدیم میشود. اجزاي تشكيل دهنده صورت هاي مالي به قرار زير است:
I12: شماره صفحه
A13: • | B13: صورت سود و زیان | I13: 2
A14: • | B14: صورت وضعیت مالی | I14: 3
A15: • | B15: صورت تغییرات در حقوق مالکانه | I15: 4
A16: • | B16: صورت جریان های نقدی | I16: 5
A17: • | B17: یادداشتهای توضیحی | I17: 6-38
A18: صورتهای مالی طبق استانداردهای حسابداری تهیه شده و در تاریخ 1404/03/01 به تایید هیات مدیره شرکت رسیده است.
A20: اعضای هیات مدیره | E20: سمت | G20: امضاء
A21: دکتر حسن نوری | E21: مدیر عامل وعضو هیئت مدیره
A22: لیلا جانی پور | E22: رئیس هیئت مدیره
A23: سید حسن حسینی | E23: نائب رئیس هیئت مدیره
A26: 1

Sheet سودوزيان
A1: ='سر برگ صفحات'!A1 -> شرکت داروسازان التیام (سهامی خاص)
A2: صورت سود و زيان
A3: ='سر برگ صفحات'!A3 -> سال مالی منتهی به 30 اسفند 1403
H4: (تجدید ارائه شده)
D5: يادداشت | F5: ='سر برگ صفحات'!A7 -> سال 1403 | H5: ='سر برگ صفحات'!A8 -> سال 1402
F6: ريال | H6: ريال
B7: عمليات در حال تداوم:
B8: درآمدهاي عملياتي | D8: 5 | F8: ='درآمد یادداشت -5'!J12 -> 25841328832248 | H8: 21035845675826 | J8: 0.939869
B9: بهاي تمام شده درآمدهاي عملياتي | D9: 6 | F9: =-'بهای تمام شده یادداشت 6-'!H14 -> -23118161982897 | H9: -18732101306084
B10: سود ناخالص | F10: =SUM(F8:F9) -> 2723166849351 | H10: 2303744369742
B11: هزينه هاي فروش ، اداري و عمومي | D11: 7 | F11: ='هزینه های یادداشت -7'!G34*-1 -> -3428911757601 | H11: -2340589273651
B12: ساير درآمدها | D12: 8 | F12: ='سایردرآرمد و هزینه ها8-11'!G11 -> 1239028232029 | H12: 792199327608
B13: ساير هزينه ها | D13: 9 | F13: ='سایردرآرمد و هزینه ها8-11'!G21*-1 -> -7592606024 | H13: -20885771814
B14: سود عملياتي | F14: =SUM(F10:F13) -> 525690717755 | H14: 734468651885
B15: هزينه هاي مالي | D15: 10 | F15: ='سایردرآرمد و هزینه ها8-11'!G31*-1 -> -556615181954 | H15: -376455546347 | J15: =F8+'وضعيت مالي'!F19 -> 48852456275131
B16: ساير درآمدهای غيرعملياتي | D16: 11 | F16: ='سایردرآرمد و هزینه ها8-11'!G39 -> 7862213984 | H16: 6028962677 | J16: =J15/2 -> 2.4426228e+13
B17: سود عملیات در حال تداوم قبل از مالیات | F17: =SUM(F14:F16) -> -23062250215 | H17: 364042068215 | J17: 1000000000
B18: هزینه مالیات بردرآمد | D18: 24 | F18: 0 | H18: -9.1010517e+10 | J18: 9000000000 | L18: 137475262049
B19: سود (زیان)خالص | F19: =SUM(F17:F18) -> -23062250215 | H19: 2.7303155e+11 | J19: 90000000 | L19: =F17-L18 -> -160537512264
J20: 9000000000
A21: از آنجاییکه اقلام تشکیل دهنده سود و زیان جامع محدود به سود سال وتعدیلات سنواتی است،لذا صورت سود و (زیان) جامع ارائه نشده است.
A22: ='سر برگ صفحات'!A15 -> يادداشتهاي توضيحي ، بخش جدایی ناپذیر صورت هاي مالي است . | J22: =F19*0.05 -> -1.1531125e+09
A23: 2
A25: 1 با توجه به اين كه هزينه كاهش ارزش دريافتني ها در نتيجه ورشكستگي يكي از مشتريان عمده بوده، لذا طبق بند 86 استاندارد
A26: حسابداري1، براي درك عملكرد مالي شركت نمونه،‌تحت سرفصل جداگانه در صورت سود و زيان ارائه شده است .

Sheet وضعيت مالي
A1: ='سر برگ صفحات'!A1 -> شرکت داروسازان التیام (سهامی خاص)
A2: صورت وضعیت مالی
A3: در تاریخ 30 اسفند 1403
D6: يادداشت | F6: 1403/12/30 | I6: 1402/12/29 | K6: 1402/01/01
B7: دارايي ها | F7: ريال | I7: ريال | K7: ريال
B8: دارايي هاي غير جاري :
B9: دارایی هاي ثابت مشهود | D9: 12 | F9: ='60-20moin'!AC277+'60-20moin'!CY277 -> 5620002497572 | I9: 5512743567543 | K9: 5100823790408 | Q9: =F9-I9 -> 107258930029
B10: دارایی هاي نامشهود | D10: 13 | F10: ='60-20moin'!AM277+'60-20moin'!AN277+'60-20moin'!CZ277 -> 1031673229 | I10: 899164229 | K10: 866452229 | Q10: =F10-I10 -> 132509000
B11: دریافتنی های بلند مدت | D11: 14 | F11: 1452000000 | I11: 1452000000 | K11: 1452000000
B12: جمع دارایی هاي غير جاري | F12: =SUM(F9:F11) -> 5622486170801 | G12: =SUM(G9:G11) -> 0 | H12: =SUM(H9:H11) -> 0 | I12: =SUM(I9:I11) -> 5515094731772 | J12: =SUM(J9:J11) -> 0 | K12: =SUM(K9:K11) -> 5103142242637
B13: دارایی هاي جاري :
B14: پيش پرداخت ها | D14: 15 | F14: ='پیش پرداخت موجودی کالا 15-16'!G18 -> 151253545155 | I14: 62901871540 | K14: 63732245616 | Q14: =I14-F14 -> -88351673615
B15: موجودي مواد و كالا | D15: 16 | F15: ='پیش پرداخت موجودی کالا 15-16'!G25 -> 2116950470565 | I15: 1808098055424 | K15: 1202359754952 | Q15: =F15-I15 -> 308852415141
B16: دریافتنی هاي تجاری و ساير دريافتني ها | D16: 17 | F16: ='ح دریافتنی یادداشت -17'!G26 -> 14755085238391 | I16: 8625216233132 | K16: 6187738332179 | Q16: =F16-I16 -> 6129869005259 | R16: =I16-2323863917-F16 -> -6132192869176
B17: موجودی نقد | D17: 18 | F17: ='موجودی نقد یادداشت -18'!F10 -> 365352017971 | I17: 690598150329 | K17: 504868777370 | Q17: =F17-I17 -> -325246132358
B18: جمع دارایی هاي جاري | F18: =SUM(F14:F17) -> 17388641272082 | G18: =SUM(G14:G17) -> 0 | H18: =SUM(H14:H17) -> 0 | I18: =SUM(I14:I17) -> 11186814310425 | J18: =SUM(J14:J17) -> 0 | K18: =SUM(K14:K17) -> 7958699110117
B19: جمع دارایی ها | F19: =F12+F18 -> 23011127442883 | G19: =G12+G18 -> 0 | H19: =H12+H18 -> 0 | I19: =I12+I18 -> 16701909042197 | J19: =J12+J18 -> 0 | K19: =K12+K18 -> 13061841352754 | Q19: 5903248094555 | R19: 0.72483
B20: حقوق مالکانه و بدهی ها
B21: حقوق مالکانه
B22: سرمايه | D22: 19 | F22: ='60-20moin'!E121*-1 -> 3991339700000 | I22: 3991339700000 | K22: 20000000000
B23: اندوخته قانوني | D23: 20 | F23: =I23 -> 1.5651578e+10 | I23: 1.5651578e+10 | K23: 2000000000
B24: سود انباشته | F24: ='حقوق مالکانه'!G20 -> 5.0038255e+10 | I24: ='حقوق مالکانه'!G16 -> 1.8231313e+11 | K24: 482946808125 | Q24: 43169575044 | R24: 2.840094e+11 | S24: 14200470244
B25: مازاد تجدید ارزیابی(زمین) | F25: ='60-20moin'!E127*-1 -> 0 | I25: 0 | K25: 3971339700000
B26: جمع حقوق مالکانه | F26: =SUM(F22:F25) -> 4.0570295e+12 | G26: =SUM(G22:G25) -> 0 | H26: =SUM(H22:H25) -> 0 | I26: =SUM(I22:I25) -> 4.1893044e+12 | J26: =SUM(J22:J25) -> 0 | K26: =SUM(K22:K25) -> 4476286508125
B27: بدهی ها
B28: بدهی های غیر جاری:
B29: پرداختنی های بلند مدت | F29: 0 | I29: 0 | K29: 1656000000
B30: ذخیره مزایای پایان خدمت کارکنان | D30: 21 | F30: ='60-20moin'!E119*-1 -> 324449027696 | I30: 213684090637 | K30: 157224104216
B31: جمع بدهی های غیر جاری | F31: =SUM(F28:F30) -> 324449027696 | G31: =SUM(G28:G30) -> 0 | H31: =SUM(H28:H30) -> 0 | I31: =SUM(I28:I30) -> 213684090637 | J31: =SUM(J28:J30) -> 0 | K31: =SUM(K28:K30) -> 158880104216
B32: بدهی های جاری
B33: پرداختنی های تجاری و سایر پرداختنی ها | D33: 22 | F33: ='ح پرداختنی یادداشت -23'!G35 -> 17390297551370 | I33: 9579219830838 | K33: 7269300278370 | Q33: =F33-I33 -> 7811077720532
B34: مالیات پرداختنی | D34: 23 | F34: 0 | I34: 9.1010517e+10 | K34: 53538887183
B35: تسهیلات مالی | D35: 24 | F35: =('60-20moin'!D14+'60-20moin'!D55+'60-20moin'!E114+'60-20moin'!E115)*-1 -> 1239351330909 | I35: 2628690200902 | K35: 1103835574860 | Q35: =F35-I35 -> -1389338869993
B36: جمع بدهی های جاری | F36: =SUM(F33:F35) -> 18629648882279 | G36: =SUM(G33:G35) -> 0 | H36: =SUM(H33:H35) -> 0 | I36: =SUM(I33:I35) -> 1.2298921e+13 | J36: =SUM(J33:J35) -> 0 | K36: =SUM(K33:K35) -> 8426674740413
B37: جمع بدهی ها | F37: =F31+F36 -> 18954097909975 | G37: =G31+G36 -> 0 | H37: =H31+H36 -> 0 | I37: =I31+I36 -> 1.2512605e+13 | J37: =J31+J36 -> 0 | K37: =K31+K36 -> 8585554844629
A38: 4-7 | B38: جمع حقوق مالکانه و بدهی ها | F38: =F26+F37 -> 2.3011127e+13 | G38: =G26+G37 -> 0 | H38: =H26+H37 -> 0 | I38: =I26+I37 -> 1.6701909e+13 | J38: =J26+J37 -> 0 | K38: =K26+K37 -> 13061841352754 | R38: =I40-I19 -> -16701909042197
B41: يادداشت هاي توضيحي بخش جدایی ناپذیر صورت هاي مالي است .
A42: 3 | F42: 3
F43: =F19-F38 -> -0.3125 | G43: =G19-G38 -> 0 | H43: =H19-H38 -> 0 | I43: =I19-I38 -> -0.0625 | J43: =J19-J38 -> 0 | K43: =K19-K38 -> 0
F49: =F38-F19 -> 0.3125 | I49: =I38-I19 -> 0.0625 | J49: =J38-J19 -> 0 | K49: =K38-K19 -> 0
...

Sheet حقوق مالکانه
A1: ='سر برگ صفحات'!A1 -> شرکت داروسازان التیام (سهامی خاص)
A2: صورت تغييرات در حقوق مالكانه
A3: ='سر برگ صفحات'!A3 -> سال مالی منتهی به 30 اسفند 1403
C5: سرمایه | E5: اندوخته قانونی | G5: سود انباشته | I5: تجدیدارزیابی داراییها | K5: جمع کل
C6: ریال | E6: ریال | G6: ریال | K6: ریال
A7: مانده در 1402/01/01 | C7: 20000000000 | E7: 2000000000 | G7: 514968074100 | I7: 3971339700000 | K7: =SUM(C7:I7) -> 4508307774100
A8: اصلاح اشتباهات(یادداشت 25) | C8: 0 | E8: 0 | G8: ='تعدیلات سنواتی یادداشت -26'!H29*-1 -> -32021265975 | I8: 0 | K8: =SUM(C8:H8) -> -32021265975
A9: مانده تجدیدارائه شده در1402/01/01 | C9: =SUM(C7:C8) -> 20000000000 | E9: =SUM(E7:E8) -> 2000000000 | G9: =SUM(G7:G8) -> 482946808125 | I9: =SUM(I7:I8) -> 3971339700000 | K9: =SUM(K7:K8) -> 4476286508125
A10: تغییرات حقوق مالکانه درسال1402 | C10: 0 | E10: 0
A11: سود خالص سال 1402 | G11: =سودوزيان!H19 -> 2.7303155e+11 | K11: 2.7303155e+11
A12: اصلاح اشتباهات(یادداشت 25) | G12: =-'تعدیلات سنواتی یادداشت -26'!F29 -> -1876007376 | K12: =SUM(C12:G12) -> -1876007376
A13: تقسیم سود | G13: -558137649144 | K13: =SUM(C13:G13) -> -558137649144
A14: افزایش سرمایه | C14: 3971339700000 | I14: -3971339700000 | K14: =SUM(C14:I14) -> 0
A15: اندوخته قانونی | E15: 13651577558 | G15: -13651577558 | K15: =SUM(C15:G15) -> 0
A16: مانده در1402/12/29 | C16: =SUM(C9:C15) -> 3991339700000 | D16: =SUM(D9:D15) -> 0 | E16: =SUM(E9:E15) -> 15651577558 | F16: =SUM(F9:F15) -> 0 | G16: =SUM(G9:G15) -> 1.8231313e+11 | H16: =SUM(H9:H15) -> 0 | I16: =SUM(I9:I15) -> 0 | J16: =SUM(J9:J15) -> 0 | K16: =SUM(K9:K15) -> 4.1893044e+12 | L16: 4551477349144 | M16: =L16-K16 -> 3.6217295e+11
A17: تغییرات حقوق مالکانه درسال 1403 | E17: 0 | G17: 0 | K17: 0
A18: زیان خالص سال 1403 | C18: 0 | E18: 0 | G18: =سودوزيان!F19 -> -23062250215 | I18: 0 | K18: =SUM(C18:I18) -> -23062250215 | M18: -23062250215 | O18: 2.7303155e+11
A19: تقسیم سود | E19: 0 | G19: -109212619643 | I19: 0 | K19: =SUM(C19:I19) -> -109212619643
A20: مانده در 1402/12/29 | C20: =SUM(C16:C18) -> 3991339700000 | E20: =SUM(E16:E19) -> 15651577558 | G20: =SUM(G16:G19) -> 5.0038255e+10 | I20: =SUM(I16:I19) -> 0 | K20: =SUM(K16:K19) -> 4.0570295e+12
A23: يادداشت هاي توضيحي همراه، بخش جدایی ناپذیر صورت هاي مالي است .
A27: 4
C45: 3

Sheet جريان هاي نقدي
A1: ='سر برگ صفحات'!A1 -> شرکت داروسازان التیام (سهامی خاص)
A2: صورت جريان هاي نقدي
A3: ='سر برگ صفحات'!A3 -> سال مالی منتهی به 30 اسفند 1403
C5: يادداشت | E5: ='سر برگ صفحات'!A7 -> سال 1403 | G5: ='سر برگ صفحات'!A8 -> سال 1402
E6: ریال | G6: ریال
B7: جریان های نقدی حاصل از فعاليتهاي عملياتي:
B8: نقد حاصل از عملیات | C8: 26 | E8: 1909436698026 | G8: -424272027317 | O8: 82015616484 | P8: =E8-O8 -> 1827421081542
B9: پرداخت های نقدی بابت مالیات بر درآمد | E9: -9.1010517e+10 | G9: -53538887183
B10: جریان خالص ورود (خروج) نقد حاصل از فعالیت های عملیاتی | E10: =SUM(E8:E9) -> 1.8184262e+12 | G10: -477810914500
B11: جریان های نقدی حاصل از فعالیت های سرمایه گذاری :
B12: پرداخت های نقدی برای خرید دارایی های ثابت مشهود | E12: =-'دارایی ثابت 12'!T12-'دارایی ثابت 12'!T13 -> -198140956614 | G12: -485320364280
B13: پرداخت های نقدی برای خرید دارایی های نامشهود | E13: =-'دارایی نامشهود-13'!H11 -> -132509000 | G13: -32712000
B14: دریافت های نقدی حاصل از سود اوراق | E14: ='سایردرآرمد و هزینه ها8-11'!G38 -> 110398064 | G14: 325863710 | Q14: =2406637199332-1200000000 -> 2405437199332
B15: دریافت های نقدی حاصل از سود سپرده بانکی | E15: ='سایردرآرمد و هزینه ها8-11'!G36 -> 444806167 | G15: 168420334
B16: وجوه دریافتی ازشرکت های گروه | V16: 1402 | X16: 1401
B17: جریان خالص خروج نقد حاصل از فعالیت های سرمایه گذاری | E17: =SUM(E12:E16) -> -197718261383 | G17: -484858792236 | S17: تسهیلات | V17: ریال | X17: ریال
B18: جریان خالص خروج نقد قبل از فعالیت های تامین مالی | E18: =E10+E17 -> 1.6207079e+12 | G18: -962669706736 | S18: مانده در ابتدای دوره اصل | V18: 1303692014827 | X18: 798680572284
B19: جریان های نقدی حاصل از فعاليتهاي تامین مالی : | S19: مانده ابتدای دوره بهره | V19: 115347240634 | X19: 56535263670
B20: دریافت های نقدی حاصل از تسهیلات | E20: ='تسهیلات یادداشت -25'!G55+'تسهیلات یادداشت -25'!O61 -> 2405437199332 | G20: 4192500000000 | O20: =Q20+P20 -> 1643171480000 | P20: -227828520000 | Q20: 1871000000000 | S20: دریافتهای نقدی | V20: 3971000000000 | W20: 0 | X20: 2459000000000
B21: پرداختهای نقدی بابت اصل تسهیلات | E21: ='تسهیلات یادداشت -25'!G57 -> -3805519612029 | G21: -2680732945091 | O21: =Q21-P21 -> 1536231480000 | P21: 67588520000 | Q21: 1603820000000 | S21: سود و کارمزد جرائم | V21: 496751079051 | X21: 239592093473
B22: پرداختهای نقدی بابت سود تسهیلات | E22: =('تسهیلات یادداشت -25'!G58-'سایردرآرمد و هزینه ها8-11'!G28-'سایردرآرمد و هزینه ها8-11'!G29-'سایردرآرمد و هزینه ها8-11'!G30)-7531514862 -> -545871639250 | G22: -363367975214 | O22: 7531415862 | S22: پرداختی بابت اصل | V22: -2680732945091 | X22: -1953988557457
B23: جریان خالص ورود نقد حاصل از فعالیت های تامین مالی | E23: =SUM(E20:E22) -> -1945954051947 | G23: 1148399079695 | O23: =1389338869171 -> 1389338869171 | P23: =E23+O23 -> -556615182776 | S23: پرداختهای نقد بابت سود | V23: -347375086812 | W23: 0 | X23: -180780116509
B24: خالص افزایش در موجودی نقد | E24: =E23+E18 -> -3.2524613e+11 | G24: 185729372959 | O24: =E23+O23 -> -556615182776 | S24: مانده | V24: 2858682302609 | X24: 1419039255461
B25: مانده موجودی نقد در ابتدای سال | E25: ='وضعيت مالي'!I17 -> 690598150329 | G25: 504868777370 | S25: کسر می گردد سود و كارمزد سال هاي آتي(یادداشت 16 صورتهای مالی ) | V25: -229992101707 | X25: -93703680601
B26: مانده موجودی نقد در پایان سال | E26: =E24+E25 -> 3.6535202e+11 | G26: 690598150329 | I26: 365352017971 | L26: 690598150329 | S26: کسر می شود(سپرده مسدودی تسهیلات | V26: 0 | X26: -221500000000
S27: مانده پایان دوره | V27: 2628690200902 | X27: 1103835574860
A28: يادداشت هاي توضيحي همراه، بخش جدایی ناپذیر صورت هاي مالي است .
A29: 5
E35: ='وضعيت مالي'!F17 -> 365352017971 | G35: ='وضعيت مالي'!I17 -> 690598150329
E36: =E24+E25 -> 3.6535202e+11 | F36: =F24+F25 -> 0 | G36: =G24+G25 -> 690598150329
E37: =E35-E36 -> -0.25 | F37: =F26-F36 -> 0 | G37: =G26-G36 -> 0
A70: 9

Sheet تاريخچه
A1: ='سر برگ صفحات'!A1 -> شرکت داروسازان التیام (سهامی خاص)
A2: يادداشتهاي توضيحي صورتهاي مالي
A3: ='سر برگ صفحات'!A3 -> سال مالی منتهی به 30 اسفند 1403
A5: -1 | B5: تاریخچه وفعالیت
A6: -1-1 | B6: تاریخچه
B7: شرکت داروسازان التیام(سهامی خاص) در تاریخ 1381/03/17 و طی شماره 187736 در اداره کل ثبت شرکتها و مالکیتهای صنعتی واقع در تهران به ثبت رسیده است/ مرکز اصلی شرکت تهران - کیلومتر 9 جاده مخصوص کرج خیابان نخ زرین خیابان شهید جلال پلاک 3 میباشد/شماره اقتصادی و شناسه ملی شرکت به شماره 411331479937 و 10102297765 می باشد.
A9: -1-2 | B9: فعالیت اصلی شرکت
B10: عمده فعالیت های شرکت، طبق ماده 2 اساسنامه عبارتست از: تولید و ساخت اقلام داروئی ، آرایشی و بهداشتی و نیز وارد کردن انواع مواد اولیه داروئی ، آرایشی و بهداشتی و هر نوع لوازم و ماشین آلات که به نحوی با ساخت دارو و لوازم آرایشی و بهداشتی مرتبط باشد/ شایان ذکر است به استناد صورتجلسه مجمع عمومی فوق العاده مورخ 1385/02/15 موضوع فعالیت شرکت به توزیع و پخش داروهای انسانی ، دامی ، آرایشی بهداشتی و لوازم و تجهیزات پزشکی و مکملهای انسانی و دامی و نیز واردات انواع داروهای ساخته شده تغییر یافت.
A12: -1-3 | B12: تعداد کارکنان
B13: تعداد کارکنان دائم و موقت شرکت طی سال مالی مورد رسیدگی به شرح زیر بوده است :
G14: ='سر برگ صفحات'!A7 -> سال 1403 | J14: ='سر برگ صفحات'!A8 -> سال 1402
G15: نفر | J15: نفر
C16: کارکنان قراردادی | G16: 591 | J16: 576
G17: =SUM(G16:G16) -> 591 | J17: =SUM(J16:J16) -> 576
A18: -2 | B18: استانداردهای حسابداری جدید وتجدید نظر شده | C18: استانداردهای جدید وتجدید نظر شده
A19: 2-1- استاندارد های حسابداری جدید و تجدید نظر شده که در سال مالی جاری لازم الاجرا شده است.
A20: اجرای استاندارد های حسابداری شماره 38 ترکیب تجاری ، 39 صورتهای مالی تلفیقی ، 18 صورتهای مالی جداگانه ،40مشارکت ها ، 41 افشای منافع در واحد های تجاری دیگر ،30سرمایه گذاری در واحد تجاری وابسته و مشارکت خاص و 42 اندازه گیری ارزش منصفانه که از ابتدای سال مالی جاری برای شرکت ها لازم الاجرا است دارای آثار با اهمیتی بر روی صورتهای مالی نمی باشد.
A23: -3 | B23: اهم رويه هاي حسابداري1
A24: -3-1 | B24: مباني اندازه گيري استفاده شده در تهيه صورتهاي مالي
A25: -3-1-1 | B25: صورت های مالی برمبنای بهای تمام شده تاریخی تهيه شده است،به استثنای موارد ذیل که به ارزش تجدید ارزیابی است.
A26: الف-دارائی ثابت مشهود-طبقه بندی زمین برمبنای روش تجدید ارزیابی (یادداشت توضیحی 3-4-2)
A27: 6
A29: 1 رويه هاي حسابداري كه در شركت موضوعيت ندارد،‌ نبايد افشا شود.

Sheet اهم رويه1
A1: ='سر برگ صفحات'!A1 -> شرکت داروسازان التیام (سهامی خاص)
A2: ='سر برگ صفحات'!A16 -> يادداشتهاي توضيحي صورت هاي مالي
A3: ='سر برگ صفحات'!A3 -> سال مالی منتهی به 30 اسفند 1403
A4: -3-2 | B4: درآمد عملیاتی
A5: -3-2-1 | B5: در آمد عملیاتی به ارزش منصفانه مابه ازای دریافتی یا دریافتنی و به کسر مبالغ برآوردی از بابت برگشت از فروش وتخفیفات اندازه گیری می شود .
A7: -3-2-2 | B7: درآمد عملیاتی حاصل از فروش کالادر زمان تحویل کالا به مشتری شناسایی می شود ، توضیح اینکه نرخ فروش دارو بر اساس مصوبات سازمان غذا و داروی وزارت بهداشت ، درمان و آموزش پزشکی تعیین می گردد. | C7: درآمد عملیاتی حاصل از فروش کالادر زمان تحویل کالا به مشتری شناسایی می شود .
A8: -3-2-3 | B8: درآمد ارائه خدمات ،در زمان ارائه خدمات ،شناسایی می گردد . | C8: درآمد ارائه خدمات ،در زمان ارائه خدمات ،شناسایی می گردد .
A10: -3-3 | B10: مخارج تامین مالی
B11: مخارج تامین مالی در دوره وقوع به عنوان هزینه شناسایی می شود، به استثنای مخارجی که مستقیما قابل انتساب به تحصیل «دارایی های واجد شرایط» است.
A14: -3-4 | B14: دارایی های ثابت مشهود
A15: -3-4-1 | B15: داريي هاي ثابت مشهود، بر مبناي بهاي تمام شده اندازه گیری می شود .مخارج بهسازی و تعمیرات اساسی که باعث افزایش قابل ملاحظه در ظرفیت یا عمر مفید داراییهای ثابت یا بهبود اساسی در کیفیت بازدهی آنها میگردد ، به عنوان مخارج سرمایه ای محسوب و طی عمر مفید باقیمانده داراییهای ثابت مربوط مستهلک میشود .هزینه های تعمیرات و نگهداری جرئی که بمنظور حفظ یا ترمیم منافع اقتصادی مورد انتظار واحد تجاری از استاندارد عملکرد ارزیابی شده اولیه دارایی انجام میشود ، هنگام وقوع به عنوان هزینه های جاری تلقی و به حساب سود و زیان دوره منظور می شود.
A16: -3-4-2 | B16: در سال مالی 1401 به استناد اصلاحیه ماده 10 آئین نامه اجرایی تبصره (1)ماده 149 قانون مالیاتهای مستقیم مصوب 1366/12/03 با اصلاحات والحاقات بعدی آن ،دارایی های ثابت مشهود (زمین)مورد تجدید ارزیابی قرارگرفته است ومازاد حاصل از تجدید ارزیابی به استناد ماده 14 قانون (حداکثر استفاده از توان تولیدی وخدماتی کشور وحمایت از کالای ایرانی )به حساب سرمایه منظور گردیده است.
A17: -3-4-3 | B17: استهلاک دارایی های ثابت مشهود باتوجه به الگوی مصرف منافع اقتصادی آتی مورد انتظار (شامل عمرمفید برآوردی) دارایی های مربوط و با در نظر گرفتن آیین نامه استهلاکات موضوع ماده 149 و بخشنامه شماره 200-95-78 مورخ 1395/11/04 و براساس نرخ ها و روش های جدول زير محاسبه می شود:
C18: نوع دارایی | E18: نرخ استهلاک | I18: روش استهلاک
C19: ساختمان | E19: 25 | I19: خط مستقیم
C20: ماشین آلات وتجهیزات | E20: 6 | I20: خط مستقیم
C21: وسایل نقلیه | E21: 6 | I21: خط مستقیم
C22: اثاثه و منصوبات | E22: 3و5و6 | I22: خط مستقیم
A25: 7

Sheet اهم رويه 2
A1: ='سر برگ صفحات'!A1 -> شرکت داروسازان التیام (سهامی خاص)
A2: ='سر برگ صفحات'!A16 -> يادداشتهاي توضيحي صورت هاي مالي
A3: ='سر برگ صفحات'!A3 -> سال مالی منتهی به 30 اسفند 1403
A5: -3-4-4 | B5: برای دارایی های ثابتی که طی ماه تحصیل و مورد بهره برداری قرار می گیرد، استهلاک از اول ماه بعد محاسبه و در حساب ها منظور می شود. در مواردی که هر یک از دارایی های استهلاک پذیر پس از آمادگی جهت بهره برداری به علت تعطیل کار یا علل دیگر مورد استفاده قرار نگیرد، میزان استهلاک آن برای مدت یاد شده معادل 30درصد نرخ استهلاک منعکس در جدول بالا ست . در این صورت چنانچه محاسبه استهلاک بر حسب مدت باشد 70. مدت زمانی که دارایی مورد استفاده قرار نگرفته است،به باقی مانده مدت تعیین شده برای استهلاک دارایی در این جدول اضافه خواهد شد.
A7: -3-4-5 | B7: استهلاک دارایی های تجدید ارزیابی شده با توجه به مبلغ دفتری جدید (پس از تجدید ارزیابی)، طی عمر مفید باقی مانده محاسبه ودر حسابها منظور می شود .
A8: -3-5 | B8: مازاد تجدید ارزیابی
A9: -3-5-1 | B9: افزایش مبلغ دفتری یک دارایی ثابت مشهود در نتیجه تجدید ارزیابی آن (درآمدغیر عملیاتی تحقق نیافته ناشی از تجدید ارزیابی )مستقیما تحت عنوان مازاد تجدید ارزیابی ثبت ودر صورت وضعیت مالی به عنوان بخشی از حقوق مالکانه طبقه بندی می شود .هرگاه افزایش مزبور عکس یک کاهش قبلی ناشی از تجدید ارزیابی باشد که به عنوان هزینه شناسایی گردیده است،در این صورت،این افزایش تا میزان هزینه قبلی شناسایی شده در رابطه با همان دارایی به عنوان درآمد به سودوزیان دوره منظور می گردد.
A11: -3-5-2 | B11: کاهش مبلغ دفتری یک دارائی ثابت مشهود در نتیجه تجدید ارزیابی آن به عنوان هزینه شناسایی می شود.هرگاه کاهش مزبور عکس یک افزایش قبلی ناشی از تجدید ارزیابی باشدکه به حساب مازاد تجدید ارزیابی منظور شده است ،در این صورت این کاهش تا میزان مازاد تجدید ارزیابی مربوط به همان دارایی به بدهکار حساب مازاد تجدید ارزیابی منظور می گرددودر صورت سود وزیان جامع انعکاس می یابد وباقیمانده به عنوان هزینه شناسایی می شود.
A12: -3-5-3 | B12: مازادتجدید ارزیابی منعکس شده در سرفصل حقوق مالکانه،در زمان برکناری یا واگذاری دارایی مربوط یا به موازات استفاده از آن توسط شرکت،مستقیما به حساب سود انباشته منظور شود-مبلغ مازاد قابل انتقال معادل تفاوت بین استهلاک مبتنی بر مبلغ تجدید ارزیابی دارایی واستهلاک مبتنی بر بهای تمام شده تاریخی آن است.افزایش سرمایه به طور مستقیم ،از محل مازاد تجدید ارزیابی مجاز نیست،مگر در مواردی که به موجب قانون تجویز شده باشد.
A15: -3-6 | B15: دارایی هاي نامشهود
A16: -3-6-1 | B16: دارایی های نامشهود برمبنای بهای تمام شده اندازه گیری و در حسابها ثبت می شود. مخارجی از قبیل مخارج معرفی یک محصول یا خدمت جدید مانند مخارج تبلیغات، مخارج انجام فعالیت تجاری در یک محل جدید یا با یک گروه جدید از مشتریان مانند مخارج آموزش کارکنان، و مخارج اداری، عمومی وفروش در بهای تمام شده دارایی نامشهود منظور نمی شود .شناسایی مخارج در مبلغ دفتری یک دارایی نامشهود، هنگامی که دارایی آماده بهره برداری است، متوقف می شود. بنابراین مخارج تحمل شده برای استفاده یا بکارگیری مجدد یک دارایی نامشهود، در مبلغ دفتری آن منظور نمی شود.
A18: -3-6-2 | B18: استهلاک دارایی های نامشهود با عمر مفید معین، با توجه به الگوی مصرف منافع اقتصادی آتی مورد انتظار مربوط و بر اساس نرخ ها و روش های زیر محاسبه می شود :
B20: نوع دارایی | E20: نرخ استهلاک | H20: روش استهلاک
B21: نرم افزار های رایانه ای | E21: 3ساله | H21: خط مستقیم
A23: -3-7 | B23: موجودی مواد وکالا
A24: -3-7-1 | B24: موجودی مواد وکالا بر مبنای «اقل بهای تمام شده وخالص ارزش فروش» هریک از اقلام/ گروه های اقلام مشابه اندازه گیری می شود. در صورت فزونی بهای تمام شده نسبت به خالص ارزش فروش، مابه التفاوت به عنوان زیان کاهش ارزش موجودی شناسایی می شود . بهای تمام شده موجودی ها با بکارگیری روش های زیر تعیین می گردد:
F26: روش مورد استفاده
B27: کالای آماده فروش | F27: میانگین موزون
A28: -3-8 | B28: ذخيره مزاياي پايان خدمت
B29: ذخيره مزاياي پايان خدمت كاركنان بر اساس يك ماه آخرين حقوق ثابت و مزاياي مستمر براي هر سال خدمت آنان محاسبه و در حساب ها منظور مي شود .
A30: 3-9- مالیات بر درآمد
A31: 3-9-1 - هزینه مالیات
A32: هزینه مالیات مجموع مالیات جاری و انتقالی است .مالیات جاری و انتقالی باید در صورت سود و زیان منعکس شوند،مگر در مواردی که بر اقلام شناسایی شده در صورت سود و زیان جامع یا حقوق صاحبان سهام مرتبط .باشند.
A33: 3-9-2 - مالیات انتقالی
A34: مالیات انتقالی بر اساس تفاوت موقتی بین مبلغ دفتری دارایی ها و بدهی ها برای مقاصد گزارشگری مالی و مبالغ مورد استفاده برای مقاصد مالیاتی محاسبه می شود . در پایان هر دوره گزارشگری برای اطمینان از قابلیت بازیافت مبلغ دفتری دارایی مالیات انتقالی ، محتمل بودن وجود سود مشمول مالیات در آینده قابل پیش بینی برای بازیافت دارایی مالیات انتقالی ارزیابی می گردد و در صورت ضرورت مبلغ دفتری دارایی های مذبور تا میزان قابلیت بازیافت کاهش داده میشود . چنین کاهشی ، در صورتی برگشت داده می شود که وجود سود مشمول مالیات به میزان کافی محتمل باشد .
A36: 3-9-3 - تهاتر دارایی مالیات جاری و بدهی مالیات جاری
A37: شرکت دارایی های مالیات جاری و بدهی مالیات جاری را تنها در صورتی تهاتر می کند که :
A38: الف : حق قانونی برای تهاتر مبلغ شناسایی شده داشته باشد.
A39: ب : قصد تسویه بر مبنای خالص بازیافت و تسویه هم زمان دارایی و بدهی داشته باشد.
A40: 3-9-4 - مالیات جاری و انتقالی دوره جاری
A41: مالیات جاری و انتقالی در سود وزیان شناسایی می شود به استثنای زمانی که آن ها مربوط به اقلامی باشند که در سایر اقلام سود وزیان جامع یا مستقیما در حقوق مالکانه شناسایی می شوندکه در این خصوص مالیات جاری و انتقالی نیز به ترتیب در سایر اقلام سود وزیان جامع یا مستقیما در حقوق مالکانه شناسایی می شود.
A43: -4 | B43: قضاوت های مدیریت در فرآیند بکارگیری رویه های حسابداری و برآوردها
A44: -4-1 | B44: قضاوت های در فرآیند بکارگیری رویه های حسابداری و برآوردها
B45: برآوردي تاثيرگذار بر شركت وجود نداشته است.
A46: 8

Sheet درآمد یادداشت -5
A1: ='سر برگ صفحات'!A1 -> شرکت داروسازان التیام (سهامی خاص)
A2: =[3]HL!A14 -> يادداشتهاي توضيحي صورت هاي مالي
A3: ='سر برگ صفحات'!A3 -> سال مالی منتهی به 30 اسفند 1403
B4: 5-درآمدهاي عملياتي
J5: ='سر برگ صفحات'!A7 -> سال 1403 | L5: ='سر برگ صفحات'!A8 -> سال 1402
C6: :فروش خالص | J6: ريال | L6: ريال
C7: داخلی:
C8: داروهای انسانی وغیر داروئی | J8: =('60-20moin'!E128)*-1 -> 33069263045273 | L8: 24198328047109
A9: 5 | C9: فروش ناخالص | J9: =SUM(J8) -> 33069263045273 | L9: 24198328047109 | R9: =SUM(J8:J8)-J9 -> 0
A10: 5 | C10: برگشت از فروش | J10: =('60-20moin'!D129)*-1 -> -838994206819 | L10: -629738869686
A11: 5 | C11: تخفیفات | J11: =('60-20moin'!D130+'60-20moin'!D131+'60-20moin'!D132)*-1 -> -6388940006206 | L11: -2532743501597
C12: فروش خالص | J12: =SUM(J9:J11) -> 25841328832248 | L12: 21035845675826
B14: 5-1-خالص درآمد عملیاتی به تفکیک وابستگی اشخاص:
F15: ='سر برگ صفحات'!A7 -> سال 1403 | J15: ='سر برگ صفحات'!A8 -> سال 1402
F16: درآمد عملیاتی | H16: درصد نسبت به کل | J16: درآمد عملیاتی | L16: درصد نسبت به کل
F17: ریال | J17: ریال
C18: سایر مشتریان | F18: =J12 -> 25841328832248 | H18: =F18/F$19*100 -> 100 | J18: =L12 -> 21035845675826 | L18: =J18/J$19*100 -> 100
F19: =SUM(F18:F18) -> 25841328832248 | J19: =SUM(J18:J18) -> 21035845675826
B21: 5-2-جدول مقایسه ای درآمدهای عملیاتی و بهای تمام شده مربوط:
D22: ='سر برگ صفحات'!A7 -> سال 1403 | L22: ='سر برگ صفحات'!A8 -> سال 1402
D23: درآمد عملیاتی | F23: بهای تمام شده | H23: سود ناخالص | J23: درصد سود ناخالص به درآمد عملیاتی | L23: درصد سود ناخالص به درآمد عملیاتی
D24: ريال | F24: ريال | H24: ريال
C25: فروش خالص:
C26: داروهای انسانی وغیر داروئی | D26: =F19 -> 25841328832248 | F26: ='بهای تمام شده یادداشت 6-'!H14*-1 -> -23118161982897 | H26: =D26+F26 -> 2723166849351 | J26: =H26/D26 -> 0.10538029 | L26: 0.11
D27: =SUM(D26:D26) -> 25841328832248 | F27: =SUM(F26:F26) -> -23118161982897 | H27: =SUM(H26:H26) -> 2723166849351 | J27: =H27/D27 -> 0.10538029 | L27: =SUM(L26:L26) -> 0.11
A30: 9

Sheet درآمد یادداشت 5-3
A1: ='سر برگ صفحات'!A1 -> شرکت داروسازان التیام (سهامی خاص)
A2: =[3]HL!A14 -> يادداشتهاي توضيحي صورت هاي مالي
B3: ='سر برگ صفحات'!A3 -> سال مالی منتهی به 30 اسفند 1403
B5: 5-3- در آمد های عملیاتی به تفکیک مراکز به شرح زیر می باشد:
G6: سال 1403 | I6: سال 1402
G7: ریال | I7: ریال
C8: تهران غرب | G8: 4234228835857 | I8: 3122797094677
C9: تهران شرق | G9: 3793892890419 | I9: 3491884369100
C10: بابل | G10: 1530724087531 | I10: 1184518698313
C11: همدان | G11: 503445809542 | I11: 464146411208
C12: رشت | G12: 1098037312074 | I12: 664668167320
C13: تبریز | G13: 1033391564252 | I13: 824571819224
C14: ارومیه | G14: 1501826325161 | I14: 979058819565
C15: اصفهان | G15: 2150668280552 | I15: 1442620121194
C16: کرمان | G16: 1191874691183 | I16: 973797303320
C17: قم | G17: 1477949179066 | I17: 1071776459231
C18: قزوین | G18: 815376920302 | I18: 474941016545
C19: مشهد | G19: 2541937160310 | I19: 1614801821282
... C28: سنندج | G28: 801762773241 | I28: 509075578288
C29: فروش ناخالص | G29: =SUM(G8:G28) -> 33069263045273 | I29: =SUM(I8:I28) -> 24198328047109
C30: برگشت از فروش | G30: -838994206819 | I30: -629738869686
C31: تخفیفات | G31: -6388940006206 | I31: -2532743501597
C32: فروش خالص | G32: =G29+G30+G31 -> 25841328832248 | I32: =I29+I30+I31 -> 21035845675826
B34: 5-3-1- | C34: تمامی خریدها و فروشهای انجام شده براساس قیمتهای مصوب وزارت بهداشت انجام می شود.
B35: 5-3-2- | C35: مرکز کرج با مرکز تهران غرب ادغام گردیده ومرکز یزد با مرکز اصفهان ادغام گردیده است.
A36: 10

Sheet درآمد یادداشت 5-4
A1: ='[4]سر برگ صفحات'!A1 -> شرکت داروسازان التیام (سهامی خاص)
A2: =[3]HL!A14 -> يادداشتهاي توضيحي صورت هاي مالي
B3: ='سر برگ صفحات'!A3 -> سال مالی منتهی به 30 اسفند 1403
B5: 5-4- در آمد های عملیاتی به تفکیک محصول به شرح زیر می باشد:
E6: سال 1403 | I6: سال 1402
E7: مقدار | G7: ریال | I7: مقدار | K7: ریال
C8: قرص | E8: 15950772 | G8: 12333440759456 | I8: 14495802 | K8: 8674519925674
C9: کپسول | E9: 4450993 | G9: 5026257739051 | I9: 3929774 | K9: 2946429472115
C10: شربت | E10: 9260469 | G10: 3352533797245 | I10: 13373288 | K10: 2949843692311
C11: ویال | E11: 542556 | G11: 754876677123 | I11: 889401 | K11: 1690289905164
C12: آمپول | E12: 1371368 | G12: 1882278016309 | I12: 1439271 | K12: 1263597123640
C13: سرم | E13: 5112516 | G13: 1142310792161 | I13: 5341856 | K13: 992826735190
C14: اسپری | E14: 2282882 | G14: 887936045232 | I14: 2276050 | K14: 667644047531
C15: قطره | E15: 5962613 | G15: 1339774337843 | I15: 3751145 | K15: 635725690797
C16: سوسپانسیون | E16: 1323159 | G16: 631250965645 | I16: 1870993 | K16: 551251600050
C17: محلول | E17: 747914 | G17: 575445963393 | I17: 631875 | K17: 388949039126
C18: شیاف | E18: 1597483 | G18: 418043419025 | I18: 1838915 | K18: 337891104935
C19: پماد | E19: 2114555 | G19: 554474965710 | I19: 1606599 | K19: 318524469213
... C35: سر شیشه | E35: 13336 | G35: 11937328428 | I35: 34386 | K35: 28630330499
C36: پد | E36: 0 | I36: 80373 | K36: 22427494722
C37: اسکراب | E37: 17401 | G37: 46306874880 | I37: 7872 | K37: 18878192640
C38: کپسول مایع | E38: 187269 | G38: 226093587548 | I38: 21012 | K38: 23963551574
C39: لوسیون | E39: 125189 | G39: 26647611951 | I39: 77803 | K39: 17239679223
C40: ست | E40: 0 | G40: 0 | I40: 1410 | K40: 8128512000
C41: بالک | E41: 848 | G41: 4380500000 | I41: 1789 | K41: 6673625000
C42: صابون | E42: 39510 | G42: 23633299226 | I42: 24831 | K42: 7303789742
C43: ویال خوراکی | E43: 10109 | G43: 23905176476 | I43: 3554 | K43: 5875624607
C44: قلم | E44: 357 | G44: 283399030 | I44: 29871 | K44: 5246183988
C45: سایر | E45: 164457 | G45: 119674941198 | I45: 26598 | K45: 14123138631
C46: فروش ناخالص | G46: =SUM(G8:G45) -> 33069263045273 | K46: =SUM(K8:K45) -> 24198328047109
C47: برگشت از فروش | G47: -838994206819 | K47: -629738869686
C48: تخفیفات | G48: -6388940006206 | K48: -2532743501597
C49: فروش خالص | G49: =G46+G47+G48 -> 25841328832248 | K49: =K46+K47+K48 -> 21035845675826
B52: 5-5- | C52: برگشت از فروش مربوط به مرجوعی کالا توسط مشتریان و مبالغ تخفیفات براساس مبالغ فروش محاسبه واعطاءگردیده است.
B53: 11

Sheet بهای تمام شده یادداشت 6-
A1: ='[5]سر برگ صفحات'!A1 -> شرکت داروسازان التیام (سهامی خاص)
A2: =[6]HL!A14 -> يادداشتهاي توضيحي صورت هاي مالي
A3: ='[5]سر برگ صفحات'!A3 -> سال مالی منتهی به 30 اسفند 1403
A5: 6- | B5: بهای تمام شده درآمدهای عملیاتی
F6: یادداشت | H6: ='[5]سر برگ صفحات'!A7 -> سال 1403 | J6: سال 1402
H7: ریال | J7: ریال
B8: موجودی کالا در ابتدای سال | F8: 16 | H8: 1808098055424 | J8: 1202359754952
B9: خرید خالص طی سال | F9: 6-1 | H9: 25105586076654 | J9: 19836428358097
B10: موجودی کالای آماده برای فروش | H10: =SUM(H8:H9) -> 26913684132078 | J10: =SUM(J8:J9) -> 21038788113049
B11: کسر می شود:
B12: تعدیلات موجودی انبار | F12: 6-2 | H12: -1678571678616 | J12: -498588751541
B13: موجودی کالا در پایان سال | F13: 16 | H13: -2116950470565 | J13: -1808098055424
B14: بهای تمام شده کالای فروش رفته | H14: =SUM(H10:H13) -> 23118161982897 | J14: =SUM(J10:J13) -> 18732101306084
A16: 6-1- | B16: در سال مورد گزارش مبلغ 25/105/586 میلیون ریال (سال قبل 19/836/428 میلیون ریال) موجودی کالا خریداری شده است. تامین کنندگان اصلی موجودی کالا از کشور ایران می باشد و مبلغ خرید از هریک به شرح زیر است:
D18: ='[5]سر برگ صفحات'!A7 -> سال 1403 | H18: ='[5]سر برگ صفحات'!A8 -> سال 1402
B19: شرکتهای فروشنده | D19: ریال | F19: درصد نسبت به کل خرید سال | H19: ریال | J19: درصد نسبت به کل خرید سال
B20: خوارزمی | D20: 3520656020262 | F20: =IFERROR(D20/H$9,0) -> 0.14023397 | H20: 3452923460863 | J20: =IFERROR(H20/J$9,0) -> 0.17406982
B21: کیمیا الکل زنجان | D21: 717831794020 | F21: =IFERROR(D21/H$9,0) -> 0.028592513 | H21: 461570433744 | J21: =IFERROR(H21/J$9,0) -> 0.023268828
B22: فرآورده ها تزریقی ایران | D22: 227970908000 | F22: =IFERROR(D22/H$9,0) -> 0.0090804854 | H22: 900790556120 | J22: =IFERROR(H22/J$9,0) -> 0.045410925
B23: رها | D23: 1050224207726 | F23: =IFERROR(D23/H$9,0) -> 0.041832292 | H23: 1303093885911 | J23: =IFERROR(H23/J$9,0) -> 0.065691961
B24: اکسیر | D24: 1743715116395 | F24: =IFERROR(D24/H$9,0) -> 0.069455264 | H24: 2870032106732 | J24: =IFERROR(H24/J$9,0) -> 0.14468492
B25: خوش طعم افزر | D25: 0 | F25: =IFERROR(D25/H$9,0) -> 0 | H25: -6187500 | J25: =IFERROR(H25/J$9,0) -> -3.1192611e-07
B26: سپهر پلاستیک پدیده | D26: -12073471340 | F26: =IFERROR(D26/H$9,0) -> -0.00048090777 | H26: 15328330075 | J26: =IFERROR(H26/J$9,0) -> 0.00077273639
B27: آنوشا(تسنیم) | D27: 1471264085606 | F27: =IFERROR(D27/H$9,0) -> 0.058603057 | H27: 1106577183109 | J27: =IFERROR(H27/J$9,0) -> 0.055785102
B28: واریان فارمد | D28: 1343612764845 | F28: =IFERROR(D28/H$9,0) -> 0.053518478 | H28: 473844965680 | J28: =IFERROR(H28/J$9,0) -> 0.023887615
B29: حکیم | D29: 97611973220 | F29: =IFERROR(D29/H$9,0) -> 0.0038880579 | H29: 241224602356 | J29: =IFERROR(H29/J$9,0) -> 0.012160687
B30: پارس دارو | D30: 1024321578071 | F30: =IFERROR(D30/H$9,0) -> 0.040800544 | H30: 471965566971 | J30: =IFERROR(H30/J$9,0) -> 0.02379287
B31: پدیده شیمی قرن | D31: -133690680 | F31: =IFERROR(D31/H$9,0) -> -5.3251368e-06 | H31: 44788249920 | J31: =IFERROR(H31/J$9,0) -> 0.0022578787
... B46: سایر تامین کنندگان | D46: 6646355186314 | F46: =IFERROR(D46/H$9,0) -> 0.26473611 | H46: 3908363694655 | J46: =IFERROR(H46/J$9,0) -> 0.19702961
B47: جمع کل | D47: =SUM(D20:D46) -> 25105586076654 | F47: =SUM(F20:F46) -> 1 | H47: =SUM(H20:H46) -> 19836428358097 | J47: =SUM(J20:J46) -> 1 | M47: =J9-H47 -> 0
A49: 12
A51: 6-2- | B51: تعدیلات موجودی انبار:
H52: سال 1403 | J52: سال 1402
H53: ریال | J53: ریال
B54: تعدیلات انبار - اصلاح بچ | H54: 2199905419 | J54: 1978110277
B55: ضایعات | H55: 0 | J55: 0
B56: امحاء ضایعات | H56: -8872039665 | J56: -20196599014
B57: جوایز | H57: -2218341471634 | J57: -683491226683
B58: انحراف قیمت | H58: 546441927264 | J58: 203120963879
H59: =SUM(H54:H58) -> -1678571678616 | I59: =SUM(I54:I58) -> 0 | J59: =SUM(J54:J58) -> -498588751541
...

Sheet هزینه های   یادداشت -7
B1: ='سر برگ صفحات'!A1 -> شرکت داروسازان التیام (سهامی خاص)
B2: =[6]HL!A14 -> يادداشتهاي توضيحي صورت هاي مالي
B3: ='سر برگ صفحات'!A3 -> سال مالی منتهی به 30 اسفند 1403
B4: 7- | C4: هزینه های فروش ، اداری و عمومی
E6: یادداشت | G6: ='سر برگ صفحات'!A7 -> سال 1403 | I6: ='سر برگ صفحات'!A8 -> سال 1402
G7: ریال | I7: ریال
A8: 7 | C8: حقوق و دستمزد و مزايا | E8: 7-1 | G8: ='60-20moin'!CN277 -> 1533062825457 | I8: 1052171039382
A9: 7 | C9: پاداش بهره وری | G9: ='60-20moin'!CO277 -> 608228679153 | I9: 369451856275
C10: حق الزحمه و حق المشاوره | G10: ='60-20moin'!DP277 -> 35272696266 | I10: 32000252404
A11: 7 | C11: حق بیمه | E11: 7-2 | G11: ='60-20moin'!CR277 -> 275981632583 | I11: 188202705523
A12: 7 | C12: هزینه حمل | G12: ='60-20moin'!DA277 -> 193388664837 | I12: 163311640610
A13: 7 | C13: اجاره وسائط نقلیه | G13: ='60-20moin'!DQ277 -> 10027183333 | I13: 6920733333
A14: 7 | C14: اجاره انبار | G14: ='60-20moin'!DR277 -> 35232750002 | I14: 27187333332
A15: 7 | C15: عیدی و پاداش | G15: ='60-20moin'!CP277 -> 104719532287 | I15: 71416403236
A16: 7 | C16: هزینه استهلاک | G16: ='60-20moin'!CX277 -> 90882026585 | I16: 73400587145
A17: 7 | C17: سنوات خدمت | G17: ='60-20moin'!CQ236 -> 144575446544 | I17: 87606116731
A18: 7 | C18: مرخصی استفاده نشده | G18: ='60-20moin'!CQ235 -> 7250846950 | I18: 7683770551
A19: 7 | C19: اقامت و ماموریت | G19: ='60-20moin'!DM277 -> 10745908908 | I19: 7782891858
A20: 7 | C20: نوشت افزار -ملزومات مصرفی و ملبوسات | G20: ='60-20moin'!DD277 -> 185568399188 | I20: 115400878522
A21: 7 | C21: آب و برق و گاز مصرفی و تلفن | G21: ='60-20moin'!DE277 -> 32509273933 | I21: 24963095377
A22: 7 | C22: آگهي وتبليغات و بازاریابی | G22: ='60-20moin'!DU277 -> 167416100 | I22: 48677875
A23: 7 | C23: آبدارخانه وپذيرائي | G23: ='60-20moin'!DG277 -> 13277136928 | I23: 8351780061
A24: 7 | C24: بيمه دارائي ثابت | G24: ='60-20moin'!DI277 -> 27642525575 | I24: 20550070384
C25: پشتیبانی نرم افزار و اشتراک اینترنت | G25: ='60-20moin'!DL277 -> 11148485405 | I25: 5914707000
A26: 7 | C26: تعمير ونگهداري دارایی ثابت | G26: ='60-20moin'!DB277 -> 43625059924 | I26: 27280693566
A27: 7 | C27: ایاب و ذهاب | G27: ='60-20moin'!DS277 -> 2999396040 | I27: 2039943496
A28: 7 | C28: بهداشت و درمان | G28: ='60-20moin'!DC277 -> 1905481560 | I28: 1601878833
A29: 7 | C29: سوخت وسایط نقلیه | G29: ='60-20moin'!DH277 -> 12157632341 | I29: 9702257624
A30: 7 | C30: بیمه تکمیلی و مسئولیت مدنی | G30: ='60-20moin'!DT277 -> 32924945177 | I30: 25661935469
C31: هزینه حسابرسی | G31: ='60-20moin'!DW277 -> 2097754501 | I31: 1185900285
A32: 7 | C32: حق حضور در جلسات هیات مدیره | G32: ='60-20moin'!DF277 -> 1440000000 | I32: 960000000
A33: 7 | C33: سایر | G33: ='60-20moin'!EA277 -> 12080058024 | I33: 9792124779
A34: 7 | C34: جمع کل | G34: =SUM(G8:G33) -> 3428911757601 | I34: =SUM(I8:I33) -> 2340589273651
B36: -7-1 | C36: افزایش مبالغ مربوط به حقوق ودستمزد براساس ضوابط ودستورالعمل ها وبخشنامه های ابلاغی سازمان تامین اجتماعی صورت پذیرفته است.
A37: 14 | B37: 7-2- | C37: افزایش بیمه سهم کارفرما بابت افزایش سالانه حقوق و دستمزد پرسنل می باشد.
B38: 14

Sheet سایردرآرمد و هزینه ها8-11
A1: ='سر برگ صفحات'!A1 -> شرکت داروسازان التیام (سهامی خاص)
B2: =[6]HL!A14 -> يادداشتهاي توضيحي صورت هاي مالي
A3: ='سر برگ صفحات'!A3 -> سال مالی منتهی به 30 اسفند 1403
B4: 8- | C4: سایر درآمد ها
E5: یادداشت | G5: ='سر برگ صفحات'!A7 -> سال 1403 | I5: ='سر برگ صفحات'!A8 -> سال 1402
G6: ریال | I6: ریال
A7: 8 | C7: ='60-20moin'!C134 -> جوایز فروش | E7: 8-1 | G7: ='60-20moin'!EI277*-1 -> 148952477 | I7: 28432972
C8: ='60-20moin'!C136 -> تخفیفات ریالی تامین کنندگان | E8: 8-2 | G8: ='60-20moin'!EE277*-1 -> 989342546404 | I8: 719016416569
C9: ='60-20moin'!C137 -> انحراف قیمت کاهنده و افزاینده | E9: 8-3 | G9: ='60-20moin'!ED277*-1 -> 247382392577 | I9: 72053406049
C10: تعدیلات انبار-اصلاح بچ | E10: 8-4 | G10: ='60-20moin'!EJ277*-1 -> 2154340571 | I10: 1101072018
G11: =SUM(G7:G10) -> 1239028232029 | I11: =SUM(I7:I10) -> 792199327608
B13: 8-1- | C13: جوایز فروش براساس نامه های تامین کنندگان تجاری وبخشنامه های صادره از طرف وزارت بهداشت و براساس فروش به مشتریان درفاکتورفروش محاسبه ودر سرفصل جوایز فروش ثبت می گردد. | O13: جوایز فروش براساس نامه های تامین کنندگان تجاری وبخشنامه های صادره از طرف وزارت بهداشت و براساس فروش به مشتریان درفاکتورفروش محاسبه ودر سرفصل جوایز فروش ثبت می گردد.
B14: 8-2- | C14: تخفیفات ریالی تامین کنندگان براساس نامه تامین کنندگان وتعیین مبالغ فروش به صورت ماهیانه ودر صورت تحقق فروش به عنوان تخفیفات ریالی درحسابها ثبت می گردد.
B15: 8-3- | C15: انحراف قیمت کاهنده وافزاینده شامل تفاوت نرخ آن دسته از موجودی هایی است که در زمان تغییر قیمت کالا متعلق در حسابها اصلاح وثبت میگردد.
B16: 8-4- | C16: تعدیلات انبار ناشی از اصلاح بچ نامبرهای کالا میباشد
B17: 9- | C17: سایر هزینه ها
G18: ='سر برگ صفحات'!A7 -> سال 1403 | I18: ='سر برگ صفحات'!A8 -> سال 1402
G19: ریال | I19: ریال
C20: هزینه امحاء ضایعات | G20: ='60-20moin'!D202 -> 7592606024 | I20: 20885771814
G21: =SUM(G20:G20) -> 7592606024 | I21: =SUM(I20:I20) -> 20885771814
B24: 10- | C24: هزینه های مالی
G25: ='سر برگ صفحات'!A7 -> سال 1403 | I25: ='سر برگ صفحات'!A8 -> سال 1402
G26: ریال | I26: ریال
C27: هزینه بهره | G27: ='60-20moin'!EL277 -> 469695912534 | I27: 359402952878
A28: 10 | C28: جرائم تسهیلات | G28: ='60-20moin'!DV207 -> 83709503887 | I28: 8886144928
C29: کارمزد بانکی | G29: ='60-20moin'!DV203+'60-20moin'!DV204 -> 3178709533 | I29: 5854238891
C30: تمبر و سفته | G30: ='60-20moin'!DV205 -> 31056000 | I30: 2312209650
G31: =SUM(G27:G30) -> 556615181954 | I31: =SUM(I27:I30) -> 376455546347 | L31: 3469805404
B33: 11- | C33: سایر درآمد های غیر عملیاتی | L33: 3439091396
G34: ='سر برگ صفحات'!A7 -> سال 1403 | I34: ='سر برگ صفحات'!A8 -> سال 1402 | L34: =L31-L33 -> 30714008
G35: ریال | I35: ریال
A36: 11 | C36: ='60-20moin'!C138 -> سود پس انداز بانکی | G36: ='60-20moin'!ER277*-1 -> 444806167 | I36: 168420334 | L36: -11209834091
A37: 11 | C37: سایر درآمدها و هزینه های غیر عملیاتی | G37: =('60-20moin'!EZ139+'60-20moin'!EZ140+'60-20moin'!EZ141)*-1 -> 7307009753 | I37: 5534678633 | L37: ='60-20moin'!#REF! -> #REF! | M37: کد71037
A38: 11 | C38: سود اوراق خزانه | G38: ='60-20moin'!EW277*-1 -> 110398064 | I38: 325863710
G39: =SUM(G36:G38) -> 7862213984 | I39: =SUM(I36:I38) -> 6028962677
B41: 11-1- | C41: سایر درآمدهای غیرعملیاتی شامل سایر در آمدها ،درآمدفروش ضایعات وسایردرآمد مشتریان می باشد.
B42: 15

Sheet دارایی ثابت 12
B1: ='[7]سر برگ صفحات'!A1 -> شرکت داروسازان التیام (سهامی خاص)
B2: يادداشتهاي توضيحي صورت هاي مالي
B3: سال مالی منتهی به 30 اسفند 1403
B4: 12- داریی های ثابت مشهود | P4: (مبالغ به ریال)
D5: زمین | F5: ساختمان | H5: ماشین آلات و تجهیزات | J5: وسایط نقلیه | L5: اثاثه و منصوبات | N5: جمع | P5: دارایی های در جریان تکمیل | R5: پیش پرداخت های سرمایه ای | T5: جمع
B6: بهای تمام شده :
B7: مانده در ابتدای سال 1402 | D7: 4162357240000 | F7: 749171940222 | H7: 0 | J7: 159552143902 | L7: 155673628448 | N7: =SUM(D7:L7) -> 5226754952572 | P7: 9869957977 | R7: 143159060383 | T7: =N7+P7+R7 -> 5379783970932
B8: افزایش | D8: 30000000000 | F8: 13214310970 | H8: 0 | J8: 7844000000 | L8: 35294370050 | N8: =SUM(D8:L8) -> 86352681020 | P8: 142675214896 | R8: 271571213761 | T8: =SUM(N8:R8) -> 500599109677
B9: واگذار شده | D9: 0 | F9: 0 | H9: 0 | J9: 0 | L9: 0 | N9: =SUM(D9:L9) -> 0 | P9: 0 | R9: -15278745397 | T9: =SUM(N9:R9) -> -15278745397
B10: سایر نقل و انتقالات و تغییرات | D10: 155000000000 | F10: 89197862249 | H10: 0 | J10: 126650119292 | L10: 5270947349 | N10: =SUM(D10:L10) -> 376118928890 | P10: 22879213329 | R10: -398998142219 | T10: =SUM(N10:R10) -> 0
B11: مانده در پایان سال 1402 | D11: =SUM(D7:D10) -> 4347357240000 | E11: =SUM(E7:E10) -> 0 | F11: =SUM(F7:F10) -> 851584113441 | G11: =SUM(G7:G10) -> 0 | H11: =SUM(H7:H10) -> 0 | I11: =SUM(I7:I10) -> 0 | J11: =SUM(J7:J10) -> 294046263194 | K11: =SUM(K7:K10) -> 0 | ... T11: =SUM(T7:T10) -> 5865104335212
B12: افزایش | D12: 0 | F12: 10529673263 | H12: 0 | J12: 9252000000 | L12: 27103991691 | N12: =SUM(D12:L12) -> 46885664954 | P12: 81758941497 | R12: 70213651616 | T12: =N12+P12+R12 -> 198858258067
B13: واگذار شده | D13: 0 | F13: 0 | H13: 0 | J13: 0 | N13: =SUM(D13:L13) -> 0 | R13: -717301453 | T13: =SUM(N13:R13) -> -717301453
B14: سایر نقل و انتقالات و تغییرات | D14: 0 | F14: =6078500000+233415374250 -> 239493874250 | H14: 0 | J14: 5775000000 | L14: 7657580000 | N14: =SUM(D14:L14) -> 252926454250 | P14: =19477002816-233415374250 -> -213938371434 | R14: -38988082816 | T14: =SUM(N14:R14) -> 0
B15: مانده در پایان سال 1403 | D15: =SUM(D11:D14) -> 4347357240000 | F15: =SUM(F11:F14) -> 1101607660954 | H15: =SUM(H11:H14) -> 0 | J15: =SUM(J11:J14) -> 309073263194 | L15: =SUM(L11:L14) -> 231000517538 | N15: =SUM(N11:N14) -> 5989038681686 | P15: =SUM(P11:P14) -> 43244956265 | R15: =SUM(R11:R14) -> 30961653875 | T15: =SUM(T11:T14) -> 6063245291826
B16: استهلاك انباشته:
B17: مانده در ابتدای سال 1402 | D17: 0 | F17: -55680290421 | G17: 0 | H17: 0 | I17: 0 | J17: -111560934398 | K17: 0 | L17: -111718955705 | M17: 0 | N17: =SUM(F17:L17) -> -278960180524 | P17: 0 | R17: 0 | T17: =N17 -> -278960180524
B18: استهلاک | D18: 0 | F18: -31123201317 | H18: 0 | J18: -22387606669 | L18: -19889779159 | N18: =SUM(F18:L18) -> -73400587145 | P18: 0 | R18: 0 | T18: =N18 -> -73400587145
B19: واگذار شده | D19: 0 | F19: 0 | H19: 0 | J19: 0 | N19: =SUM(F19:L19) -> 0 | P19: 0 | R19: 0 | T19: =N19 -> 0
B20: مانده در پایان سال 1402 | D20: =SUM(D17:D19) -> 0 | F20: =SUM(F17:F19) -> -86803491738 | H20: =SUM(H17:H19) -> 0 | J20: =SUM(J17:J19) -> -133948541067 | L20: =SUM(L17:L19) -> -131608734864 | N20: =SUM(N17:N19) -> -352360767669 | P20: =SUM(P17:P19) -> 0 | R20: =SUM(R17:R19) -> 0 | T20: =SUM(T17:T19) -> -352360767669
B21: استهلاک | D21: 0 | F21: -34072977382 | H21: 0 | J21: -35181312802 | L21: -21627736401 | N21: =SUM(D21:L21) -> -90882026585 | P21: 0 | R21: 0 | T21: =SUM(N21:R21) -> -90882026585
B22: واگذار شده | D22: 0 | F22: 0 | H22: 0 | N22: =SUM(D22:L22) -> 0 | P22: 0 | R22: 0 | T22: =SUM(N22:R22) -> 0
