Workbook
Name A: #REF!
Name A: #REF!
Name A: #REF!
Name A: #REF!
Name A: #REF!
Name A: #REF!
Name A: #REF!
Name A: #REF!
Name A: #REF!
Name A: #REF!
Name A: #REF!
Name A: #REF!
Name A: #REF!
Name A: #REF!
Name A: #REF!
Name A: #REF!
Name K488.: #REF!
Name K488.: #REF!
Name K488.: #REF!
Name K488.: #REF!
Name K488.: #REF!
Name K488.: #REF!
Name K488.: #REF!
Name K488.: #REF!
Name K488.: #REF!
Name K488.: #REF!
Name K488.: #REF!
Name K488.: #REF!
Name K488.: #REF!
Name K488.: #REF!
Name K488.: #REF!
Name K488.: #REF!
Name l: #REF!
Name l: #REF!
Name l: #REF!
Name l: #REF!
Name l: #REF!
Name l: #REF!
Name l: #REF!
Name l: #REF!
Name l: #REF!
Name l: #REF!
Name l: #REF!
Name l: #REF!
Name l: #REF!
Name l: #REF!
Name اات: #REF!
Name اات: #REF!
Name اات: #REF!
Name اات: #REF!
Name اات: #REF!
Name اات: #REF!
Name اات: #REF!
Name اات: #REF!
Name اات: #REF!
Name اات: #REF!
Name اات: #REF!
Name ت: #REF!
Name ت: #REF!
Name ت: #REF!

Sheet ص امضا
A1: شرکت داروسازی خوارزمی (سهامی خاص)
A2: صورتهاي مالي
A3: سال مالی منتهی به 30 اسفند 1403
A7: مجمع عمومی عادی صاحبان سهام
A8: با احترام
A9: به پیوست صورتهای مالی شرکت داروسازی خوارزمی (سهامی خاص ) مربوط به سال مالی منتهی به 30 اسفند 1403 تقدیم می گردد. اجزای تشکیل دهنده صورت های مالی به قرار زیر است.
L12: شماره صفحه
A13: • | B13: صورت سود و زیان | L13: 2
A14: • | B14: صورت وضعیت مالی | L14: 3
A15: • | B15: صورت تغییرات در حقوق مالکانه | L15: 4
A16: • | B16: صورت جریانهای نقدی | L16: 5
A17: • | B17: یادداشتهای توضیحی صورتهای مالی | L17: 6-39
A19: صورتهای مالی طبق استانداردهای حسابداری تهیه شده و در تاریخ 10/ 04/ 1404 به تائید هیات مدیره شرکت رسیده است.
A22: اعضای هیات مدیره | F22: سمت | K22: امضاء
A24: آقای دکتر پیمان ترحمی | F24: مدیر عامل و رئیس هیات مدیره
A26: آقای حمیدرضا رجبی خولکی | F26: نایب رئیس هیات مدیره
A28: آقای مهدی بهروزان | F28: عضو هیات مدیره
A33: 1

Sheet سودوزيان
A1: شرکت داروسازی خوارزمی (سهامی خاص)
A2: صورت سود و زيان
A3: سال مالی منتهی به 30 اسفند 1403
D6: يادداشت | F6: سال 1403 | H6: سال 1402
F7: ريال | H7: ريال
B8: عمليات در حال تداوم:
B9: درآمدهاي عملياتي | D9: 5 | F9: ='5'!H17 -> 7.7802168e+12 | H9: ='5'!L17 -> 7918324178970
B10: بهاي تمام شده درآمدهاي عملياتي | D10: 6 | F10: =-'6-1'!I34 -> -5666818827105 | H10: =-'6-1'!K34 -> -4.842614e+12 | K10: 187798078958
B11: سود ناخالص | F11: =SUM(F9:F10) -> 2.113398e+12 | H11: =SUM(H9:H10) -> 3.0757102e+12 | K11: 10157515249
B12: هزينه هاي فروش ، اداري و عمومي | D12: 7 | F12: ='6-2'!E53*-1 -> -565711325389 | H12: =-'6-2'!G53 -> -4.8035445e+11 | M12: 214534974846
B13: ساير درآمدها | D13: 8 | F13: ='8.9.10.11'!G12 -> 24102840311 | H13: ='8.9.10.11'!I12 -> 40297561007
B14: ساير هزينه ها | D14: 9 | F14: =-'8.9.10.11'!G24 -> -33007588412 | H14: =-'8.9.10.11'!I24 -> 0
B15: سود عملياتي | F15: =F11+F12+F13+F14 -> 1.5387819e+12 | H15: =SUM(H11:H14) -> 2.6356533e+12
B16: هزينه هاي مالي | D16: 10 | F16: =-'8.9.10.11'!G33 -> -350456102062 | H16: =-'8.9.10.11'!I33 -> -368228749228
B17: ساير درآمدها و هزينه هاي غيرعملياتي | D17: 11 | F17: ='8.9.10.11'!G43 -> 43486146002 | H17: ='8.9.10.11'!I43 -> 13919596124
B18: سود عملیات در حال تداوم قبل از مالیات | F18: =F15+F16+F17-1 -> 1.231812e+12 | H18: =SUM(H15:H17) -> 2.2813441e+12 | L18: =F18*0.25 -> 3.0795299e+11
B20: هزينه مالیات بر درآمد: | K20: =F18-22837331920-23353106087 -> 1.1856215e+12 | L20: =F18-'5-10'!F21-'8.9.10.11'!G41 -> 1.1386482e+12
B21: سال جاری | D21: 23 | F21: =-(F18-'8.9.10.11'!G38-'8.9.10.11'!G41-'8.9.10.11'!G9)*20% -> -2.371243e+11 | H21: =-568744101571 -> -568744101571
B22: سود خالص عملیات درحال تداوم | F22: =SUM(F18:F21) -> 9.9468765e+11 | H22: =SUM(H18:H21)-1 -> 1.7126e+12 | K22: =K20*20% -> 2.371243e+11 | L22: =L20*0.15 -> 1.7079723e+11
K25: =F18-'8.9.10.11'!G38-'8.9.10.11'!G9 -> 1.1856215e+12
A26: از آنجاییکه اجزای تشکیل دهنده سود و زیان جامع، محدود به سود خالص می باشد لذا صورت سود وزیان جامع ارائه نشده است.
A37: يادداشت هاي توضيحي همراه، بخش جدایی ناپذیر صورت هاي مالي است .
A40: 2

Sheet وضعيت مالي
B1: شرکت داروسازی خوارزمی (سهامی خاص)
B2: صورت وضعیت مالی
B3: به تاریخ 30 اسفند 1403
D5: يادداشت | F5: 1403/12/30 | H5: 1402/12/29
B6: دارايي ها | F6: ريال | H6: ريال | L6: نسبت جاری | M6: =F17/F36 -> 1.8267415
B7: دارائيهاي غير جاري : | L7: نسبت آنی | M7: =F15+F16 -> 6615250354664 | N7: =M7/F36 -> 1.3175934
B8: دارایی هاي ثابت مشهود | D8: 12 | F8: ='12-1'!AB16 -> 439656990010 | H8: ='12-1'!AB17 -> 480909584187 | L8: نسبت بدهی به ارزش افزوده | M8: =F37/F25*100 -> 121.19497 | N8: =F38/M8 -> 7.9353581e+10
B9: دارایی هاي نامشهود | D9: 13 | F9: ='13-14'!O20 -> 3818903919 | H9: ='13-14'!O21 -> 12042956142
B10: سرمايه گذاري هاي بلند مدت | D10: 14 | F10: ='13-14'!K30 -> 2245465728 | H10: ='13-14'!O30 -> 2245465728 | L10: نسبت حاشیه سود ناخالص | M10: =سودوزيان!F11/سودوزيان!F9*100 -> 27.163742
B11: جمع دارایی هاي غير جاري | F11: =SUM(F8:F10) -> 445721359657 | H11: =SUM(H8:H10) -> 495198006057 | L11: نسبت مالکانه | M11: =F25/F18*100 -> 45.208985
B12: دارایی هاي جاري : | L12: بازده دارایی | M12: =سودوزيان!F22/'وضعيت مالي'!F18*100 -> 10.34274
B13: پيش پرداخت ها | D13: 15 | F13: ='15'!J16 -> 205774526486 | H13: ='15'!L16 -> 317146340499 | L13: بازده فروش | M13: =سودوزيان!F22/سودوزيان!F9*100 -> 12.784832 | N13: =F13-H13 -> -111371814013
B14: موجودي مواد و كالا | D14: 16 | F14: ='15-16'!J76 -> 2350508618655 | H14: ='15-16'!L76 -> 3398553525339 | N14: =F14-H14 -> -1048044906684
B15: دریافتنی هاي تجاری و ساير دريافتني ها | D15: 17 | F15: ='17'!G34 -> 6547490849001 | H15: ='17'!I34 -> 4263156873776 | N15: =F15-H15 -> 2284333975225
B16: موجودی نقد | D16: 18 | F16: ='18'!H12 -> 67759505663 | H16: ='18'!J12 -> 170000824925
B17: جمع دارایی هاي جاري | F17: =SUM(F13:F16) -> 9171533499805 | H17: =SUM(H13:H16) -> 8148857564539
B18: جمع دارایی ها | F18: =F17+F11 -> 9617254859462 | H18: =H17+H11 -> 8644055570596
B19: حقوق مالکانه و بدهی ها
B20: حقوق مالکانه
B21: سرمايه | D21: 19 | F21: ='19-20-21'!P16 -> 847085000000 | H21: ='19-20-21'!P16 -> 847085000000
B22: افزایش سرمایه در جریان | F22: 0 | H22: 0
B23: اندوخته قانوني | D23: 20 | F23: ='حقوق مالكانه '!G29 -> 84708500000 | H23: ='حقوق مالكانه '!G29 -> 84708500000
B24: سود انباشته | F24: ='حقوق مالكانه '!I29 -> 3.4160698e+12 | H24: ='حقوق مالكانه '!I22 -> 2592642140732
B25: جمع حقوق مالکانه | F25: =SUM(F21:F24) -> 4.3478633e+12 | H25: =SUM(H21:H24) -> 3524435640732
B26: بدهی ها
B27: بدهی های غیر جاری
B28: ذخیره مزایای پایان خدمت کارکنان | D28: 21 | F28: ='19-20-21'!H32 -> 248684672487 | H28: ='19-20-21'!J32 -> 177158124384
B29: جمع بدهی های غیر جاری | F29: =SUM(F28:F28) -> 248684672487 | H29: =SUM(H28:H28) -> 177158124384
B30: بدهی های جاری
B31: پرداختنی های تجاری و سایر پرداختنی ها | D31: 22 | F31: ='22'!G47 -> 2820360521517 | H31: ='22'!I47 -> 2160379961990 | L31: 3007119917055 | N31: =F31-H31 -> 659980559527
B32: مالیات پرداختنی | D32: 23 | F32: ='23'!P26 -> 284864672465 | H32: ='23'!R26 -> 741103791934 | L32: =-L31 -> -3007119917055
B33: سود سهام پرداختنی | D33: 24 | F33: ='23'!H40 -> 919058527907 | H33: ='23'!J40 -> 747798525569
B34: تسهیلات مالی | D34: 25 | F34: ='25'!G11 -> 858891244323 | H34: ='25'!I11 -> 1132075227337
B35: پیش دریافت ها | D35: 26 | F35: ='26-27'!D17 -> 137531931952 | H35: ='26-27'!F17 -> 161104298650 | N35: =H35-F35 -> 23572366698
B36: جمع بدهی های جاری | F36: =SUM(F31:F35) -> 5020706898164 | H36: =SUM(H31:H35) -> 4942461805480
B37: جمع بدهی ها | F37: =F36+F29 -> 5269391570651 | H37: =H36+H29 -> 5119619929864
B38: جمع حقوق مالکانه و بدهی ها | F38: =F37+F25 -> 9.6172549e+12 | H38: =H37+H25 -> 8644055570596
A41: يادداشت هاي توضيحي همراه، بخش جدایی ناپذیر صورت هاي مالي است .
A50: 3
A51: 1 طبق بند 39 استاندارد حسابداري 1، در صورتي كه شركت(1) يك رويه حسابداري جديد را با تسري به گذشته بكار گيرد،‌(2) اقلامي از صورت هاي مالي را با تسري به گذشته تجديد ارائه نمايد يا(3) اقلامي در صورت هاي مالي را تجديد طبقه بندي كند و اين موارد اثر با اهميتي بر اطلاعات مندرج در صورت وضعيت مالي در ابتداي دوره قبل داشته باشد، بايد صورت وضعيت مالي به تاريخ ابتداي دوره قبل نيز ارائه گردد.
...

Sheet حقوق مالكانه 
B1: شرکت داروسازی خوارزمی (سهامی خاص )
B2: صورت تغييرات در حقوق مالكانه
B3: =سودوزيان!A3 -> سال مالی منتهی به 30 اسفند 1403
D10: افزایش سرمایه در جریان | E10: سرمایه | G10: اندوخته قانونی | I10: سود انباشته | K10: جمع کل
D11: ریال | E11: ریال | G11: ریال | I11: ریال | K11: ریال
B12: مانده در1402/01/01 | D12: 0 | E12: 847085000000 | G12: 84708500000 | I12: =1565852030146 -> 1565852030146 | K12: =SUM(D12:J12) -> 2497645530146 | P12: =I12-#REF! -> #REF!
B13: تغییرات حقوق مالکانه درسال 1402
B14: سود خالص گزارش شده در صورتهای مالی سال 1402 | E14: - | G14: - | I14: 1712600023376 | K14: =SUM(E14:I14) -> 1712600023376 | P14: =113053622795-384922124 -> 112668700671
B15: اصلاح اشتباهات (یادداشت 27) | D15: 0 | I15: 0 | K15: =SUM(E15:I15) -> 0 | P15: =P14-I14 -> -1599931322705
B16: سود خالص تجدید ارائه شده سال 1402 | E16: 0 | G16: 0 | I16: =I14+I15+I12 -> 3278452053522 | K16: =K14+K15+K12 -> 4210245553522
B17: سود جامع سال 1399 | E17: =SUM(E16:E16) -> 0 | G17: =SUM(G16:G16) -> 0 | I17: =SUM(I16:I16) -> 3278452053522 | K17: =SUM(K16:K16) -> 4210245553522
B18: سود سهام مصوب | D18: 0 | E18: 0 | G18: 0 | K18: =SUM(E18:I18) -> 0
B19: افزایش سرمایه در جریان | D19: 0 | E19: 0 | G19: 0 | I19: 0 | K19: =SUM(D19:J19) -> 0
B20: تخصیص به اندوخته قانونی | D20: 0 | G20: 0 | I20: 0 | K20: =SUM(E20:I20) -> 0
B21: سود سهام مصوب | E21: - | G21: - | I21: -685809912791 | K21: =I21 -> -685809912791
B22: مانده در1402/12/29 | D22: =#REF!+D19 -> #REF! | E22: =E12 -> 847085000000 | F22: =F16+F20+F21 -> 0 | G22: =G12 -> 84708500000 | I22: =I16+I20+I21+1 -> 2592642140732 | K22: =K16+K20+K21+1 -> 3524435640732 | L22: =I22='وضعيت مالي'!H24 -> TRUE | M22: =K22='وضعيت مالي'!H25 -> TRUE | O22: =I22-I15 -> 2592642140732 | P22: 661052615941 | Q22: =P22-O22 -> -1931589524791
L23: =I22-'وضعيت مالي'!H24 -> 0 | M23: =K22-'وضعيت مالي'!H25 -> 0 | Q23: =Q22+I18 -> -1931589524791
B24: تغییرات حقوق مالکانه درسال 1403
B25: سود خالص سال 1403 | D25: 0 | E25: 0 | G25: 0 | I25: =سودوزيان!F22 -> 9.9468765e+11 | K25: =SUM(D25:I25) -> 9.9468765e+11
B26: سود سهام مصوب | D26: 0 | E26: 0 | G26: 0 | I26: 0 | K26: =SUM(E26:I26) -> 0
B27: تخصیص به اندوخته قانونی | D27: 0 | E27: 0 | G27: 0 | I27: =-G27 -> 0 | K27: =SUM(E27:I27) -> 0
B28: سود سهام مصوب | E28: 0 | G28: 0 | I28: -171260002338 | K28: =I28 -> -171260002338
B29: مانده در1403/12/30 | E29: =E22+E25+E26+E27 -> 847085000000 | G29: =G22+G25+G26+G27 -> 84708500000 | I29: =I22+I25+I27+I28 -> 3.4160698e+12 | K29: =SUM(E29:I29) -> 4.3478633e+12 | L29: =I29='وضعيت مالي'!F24 -> TRUE | M29: =K29='وضعيت مالي'!F25 -> TRUE | O29: =E29*0.1 -> 84708500000 | P29: =O29-G22 -> 0
B36: يادداشت هاي توضيحي همراه، بخش جدایی ناپذیر صورت هاي مالي است .
A38: 4

Sheet جريان هاي نقدي
A1: شرکت داروسازی خوارزمی (سهامی خاص)
A2: صورت جريان هاي نقدي
A3: =سودوزيان!A3 -> سال مالی منتهی به 30 اسفند 1403
C6: يادداشت | E6: 1403 | G6: 1402 | K6: 400043400825
E7: ريال | G7: ريال
B8: جریان های نقدی حاصل از فعاليتهاي عملياتي:
B9: نقد حاصل از عملیات | C9: 28 | E9: ='28-29'!D26 -> 1.202102e+12 | G9: ='28-29'!F26 -> 4.5578662e+11
B10: پرداخت های نقدی بابت مالیات بر درآمد | E10: =-693363422572 -> -693363422572 | G10: -310638127665 | K10: ='وضعيت مالي'!H32-سودوزيان!F21 -> 9.782281e+11 | M10: ='وضعيت مالي'!#REF!-سودوزيان!H21 -> #REF!
B11: جریان خالص ورود (خروج) نقد حاصل از فعالیت های عملیاتی | E11: =SUM(E9:E10) -> 5.0873861e+11 | G11: =SUM(G9:G10) -> 1.4514849e+11 | K11: =K10-'وضعيت مالي'!F32 -> 6.9336342e+11 | M11: =M10-'وضعيت مالي'!H32 -> #REF!
B12: جریان های نقدی حاصل از فعالیت های سرمایه گذاری : | M12: ='وضعيت مالي'!H32-سودوزيان!F21 -> 9.782281e+11
B13: دریافت های نقدی حاصل از فروش دارایی های ثابت مشهود | E13: 0 | G13: 0
B14: پرداخت های نقدی برای خرید دارایی های ثابت مشهود | E14: =-('12 اصلی'!AC14+'12 اصلی'!AC13) -> -33530285259 | G14: -56332605474 | M14: ='وضعيت مالي'!F32-'جريان هاي نقدي'!M12 -> -6.9336342e+11
B15: پرداخت های نقدی برای خرید دارایی های ثابت نامشهود | E15: ='13-14'!O12 -> 0 | G15: -3573000000
B16: دریافت های نقدی حاصل از سود سهام | E16: 0 | G16: 0
B17: دریافت های نقدی حاصل از سود سرمایه گذاری ها | E17: ='8.9.10.11'!G38 -> 23353106087 | G17: 6984252778
B18: پرداخت های نقدی حاصل از افزایش سرمایه گذاری ها | E18: ='وضعيت مالي'!H10-'وضعيت مالي'!F10 -> 0 | G18: 0
B19: دریافت وجوه پرداختی به شرکتهای وابسته | E19: 0 | G19: 0
B20: جریان خالص ورود (خروج) نقد حاصل از فعالیت های سرمایه گذاری | E20: =SUM(E13:E19) -> -10177179172 | G20: =SUM(G13:G19) -> -52921352696
B21: جریان های نقدی حاصل از فعاليتهاي تامین مالی : | K21: ='وضعيت مالي'!H34+'جريان هاي نقدي'!E25+'جريان هاي نقدي'!E26 -> 858891244323 | M21: =K21-'وضعيت مالي'!F34 -> 0
B22: تاثیر تغییرات نرخ ارز | E22: 0
B23: قرض الحسنه دریافتی از سهامداران | E23: 0
B24: تامین مالی (برداشت) توسط سهامداران | E24: 0 | G24: -45804204541 | K24: -29035656716
B25: دریافت های نقدی حاصل از تسهیلات | E25: 1617529278565 | G25: 2216670733439 | I25: =E25+'وضعيت مالي'!H34 -> 2749604505902 | K25: =G25 -> 2216670733439 | M25: 2621758752281
B26: پرداختهای نقدی بابت اصل تسهیلات | E26: =-I26 -> -1890713261579 | G26: -2102406054445 | I26: =I25-'وضعيت مالي'!F34 -> 1890713261579 | K26: =K25-'وضعيت مالي'!H34 -> 1084595506102 | M26: =M25+'وضعيت مالي'!H34 -> 3753833979618
B27: پرداختهای نقدی بابت سود و جریمه تسهیلات | E27: =سودوزيان!F16 -> -350456102062 | G27: =سودوزيان!H16 -> -368228749228 | M27: =M26-'وضعيت مالي'!F34 -> 2894942735295
B28: پرداختهاي نقدي بابت سود سهام | E28: 0 | G28: -3836632260
B29: جریان خالص ورود (خروج) نقد حاصل از فعالیت های تامین مالی | E29: =SUM(E22:E28) -> -623640085076 | G29: =SUM(G22:G28) -> -303604907035
B30: خالص (کاهش) در موجودی نقد | E30: =E11+E20+E29 -> -1.2507865e+11 | G30: =G11+G20+G29+1 -> -2.1137777e+11 | I30: =E30='وضعيت مالي'!F16-'وضعيت مالي'!H16 -> FALSE
B31: مانده موجودی نقد در ابتدای سال | E31: ='وضعيت مالي'!H16 -> 170000824925 | G31: 358815487614 | I31: ='وضعيت مالي'!F16-'وضعيت مالي'!H16 -> -102241319262 | J31: =E30-I31 -> -2.2837332e+10
B32: تاثیر تغییرات نرخ ارز | E32: ='8.9.10.11'!G9 -> 22837331920 | G32: 22563104580 | M32: =G33-E31 -> -0.49951172
B33: مانده موجودی نقد در پایان سال | E33: =E30+E31+E32 -> 6.7759506e+10 | G33: =G30+G31+G32-1 -> 1.7000082e+11 | K33: =E33-'وضعيت مالي'!F16 -> 0.35351562 | M33: =G33-'وضعيت مالي'!H16 -> -0.49951172
B34: معاملات غیر نقدی | C34: 28
E35: 0 | G35: =G33-'وضعيت مالي'!H16 -> -0.49951172
E37: =E33-'وضعيت مالي'!F16 -> 0.35351562
B45: يادداشت هاي توضيحي همراه، بخش جدایی ناپذیر صورت هاي مالي است .
A46: 5
E49: =E33-'وضعيت مالي'!F16 -> 0.35351562
A87: 9

Sheet تاريخچه
A1: شرکت داروسازی خوارزمی ( سهامی خاص )
A2: يادداشتهاي توضيحي صورتهاي مالي
A3: =سودوزيان!A3 -> سال مالی منتهی به 30 اسفند 1403
A5: -1 | B5: تاریخچه وفعالیت
A6: -1-1 | B6: تاریخچه
B7: شرکت داروسازی خوارزمی به شناسه ملی 10100378232در تاریخ 1342/09/13 به صورت شرکت سهامی خاص تاسیس شد و طی شماره8941 مورخ 1342/09/13 در اداره ثبت شرکت ها و مالکیت صنعتی تهران به ثبت رسید و متعاقبا از تاریخ 1342/09/13 شروع به بهره برداری نموده است . نشانی مرکز اصلی شرکت تهران شهرک استقلال ، خیابان شهید غلامرضا جلال؛ بن بست داروسازی خوارزمی پلاک 115 طبقه همکف با کدپستی 1389716512و محل فعالیت اصلی آن در شهر تهران واقع است .
A10: -1-2 | B10: فعالیت اصلی
C11: موضوع فعاليت شركت طبق ماده 2 اساسنامه عبارت است از " تهيه و يا خريد مواد اوليه داروئي و شیمیائی اعم از مواد اولیه خام ،
C12: نيمه ساخته و ساخته شده از داخل و يا خارج از كشور،ساخت دارو و محصولات بهداشتی و آرایشی و شیمیائی ، عرضه و فروش
C13: توليدات به بازارهاي داخلي و خارجي و هر گونه عملي كه بنحو مستقيم و يا غير مستقيم به موضوع فعاليت شركت مربوط
C14: و براي جريان عادي فعاليت شركت ضرروري باشد"
C15: فعاليت شركت به موجب پروانة بهره‌برداري شماره353/21/10672 مورخ سال 1335 كه توسط وزارت صنايع - اداره كل دارو صادر
C16: گرديده ، آغاز شده است.
A17: -1-3 | B17: تعداد کارکنان
B18: میانگین ماهانه تعداد کارکنان در استخدام و نیز تعداد کارکنان شرکت های خدماتی که بخشی از امور خدماتی شرکت را به عهده دارند، طی سال به شرح زیر بوده است :
H20: 1403 | J20: 1402
H21: نفر | J21: نفر
E22: کارکنان رسمی | H22: 8 | J22: 13
E23: کارکنان قراردادی | H23: 351 | J23: 392
H24: 359 | J24: =SUM(J22:J23) -> 405
H25: =SUM(H24:H24) -> 359 | J25: =SUM(J24:J24) -> 405
A27: -2 | B27: بکارگیری استاندارهای جدید و تجدید نظر شده:
A28: -2-1 | B28: آثار با اهمیت ناشی از بکارگیری استانداردهای حسابداری جدید و تجدید نظر شده که در سال جاری لازم الاجرا هستند به شرح ذیل میباشد.
A29: -2-1-1 | B29: استاندارد های حسابداری جدیدو تجدید نظر شده مصوب که هنوز لازم الاجرا نیستند:
B30: استاندارهای حسابداری شماره18و20و38و29و40و41و42 به ترتیب صورتهای مالی جداگانه سرمایگذاری درواحدهای تجاری وابسته و مشارکت های خاص ترکیب های تجاری صورتهای مالی تلفیقی ،مشارکت ها افشای منافع در واحدهای تجاری دیگر واندازگیری ارزش منصفانه که از1400 لازم اجرا میباشد براساس ارزیابی و برآرود های صورت گرفته استانداردهای فوق باتوجه به شرایط کنونی به طور کلی تاثیر قابل ملاحظه ای برشناخت اندازگیری و گزارشگری اقلام صورت مالی نخواهند داشت.
A31: -2-2 | C31: آثار احتمال آتی با اهمیت ناشی از اجرای استاندارد های حسابداری جدید و تجدید نظر شده مصوب که هنوز لازم الجرا نیستند به شرح زیر است:
A32: -2-2-2 | C32: استاندار حسابداری16آثار تغییر برنرخ ارز آثار با اهمیت ناشی از اجرای استاندارد حسابداری 16آثار تغییر در نرخ ارز صورتهای مالی درحال حاضر برای شرکت وجود ندارد.
F34: 6

Sheet 6 اهم رويه ها
A1: شرکت داروسازی خوارزمی (سهامی خاص)
A2: یادداشتهای توضیحی صورت های مالی
A3: =سودوزيان!A3 -> سال مالی منتهی به 30 اسفند 1403
A5: 3- اهم رویه های حسابداری
A6: 3-1- مبناي تهيه صورتهاي مالي
A7: صورتهاي مالي برمبناي بهاي تمام شده تاريخي تهيه شده است.
A8: 3-2-موجودي مواد و كالا
A9: موجودي مواد و كالا به ” اقل بهاي تمام شده و خالص ارزش فروش هر یک از اقلام مشابه ” اندازه گیری مي‌شود.
A10: در صورت فزوني بهاي تمام شده نسبت به خالص ارزش فروش ، ما به ‌التفاوت به عنوان زیان كاهش ارزش موجودي شناسايي مي ‌شود. بها ي تما م شدة موجوديها با بكارگيري روشهاي زير تعيين مي‌گردد:
E13: روش مورد استفاده
B14: مواد اوليه وبسته بندي | E14: ميانگين موزون سالانه
B15: كالاي در جريان ساخت | E15: ميانگين موزون سالانه
B16: كالاي ساخته شده | E16: ميانگين موزون سالانه
B17: قطعات و لوازم يدكي | E17: ميانگين موزون سالانه
A19: 3-3-سرمايه گذاري ها
C20: نوع سرمایه گذاری | E20: نحوه اندازه گیری
B21: سرمایه گذاری های بلند مدت | C21: سرمایه گذاری در اوراق بهادار | E21: بهای تمام شده به کسر کاهش ارزش انباشته هر یک از سرمایه گذاری ها
B22: سرمایه گذاری های جاری | C22: سرمایه گذاری سریع المعامله در بازار | E22: ارزش بازار مجموعه (پرتفوی) سرمایه گذاری ها
C23: سایر سرمایه گذاری های جاری | E23: اقل بهای تمام شده و خالص ارزش فروش هریک از سرمایه گذاری ها
C24: نوع سرمایه گذاری | E24: زمان شناخت درآمد
B25: انواع سرمایه گذاری ها | C25: سایر سرمایه گذاری های جاری و بلند مدت در سهام سایر شرکتها | E25: درزمان تصویب سود توسط مجمع عمومی صاحبان سهام شرکت سرمایه پذیر ( تاتاریخ صورت وضعیت مالی)
C26: سرمایه گذاری در سایر اوراق | E26: درزمان تحقق سود تضمین شده ( باتوجه به نرخ سود موثر)
A28: 3-4-دارایی های نامشهود
A29: 3-4-1- دارایی های نا مشهود، بر مبنای بهای تمام شده اندازه گیری و در حسابها ثبت می شود. مخارجی از قبیل مخارج معرفی یک محصول یا خدمت جدید مانند مخارج تبلیغات ، مخارج انجام فعالیت تجاری در یک محل جدید یا با دارایی نامشهود منظور نمی شود. شناسایی مخارج در مبلغ دفتری یک دارایی نامشهود، هنگامی که دارایی آماده بهره برداری است ، متوقف می شود . بنابراین ، مخارج تحمل شده برای استفاده یا بکارگیری مجدد یک دارایی نامشهود ، در مبلغ دفتری آن منظور نمی شود.
A35: 3-5- داراييهاي ثابت مشهود
A36: 3-5-1- داراييها ي ثابت مشهود بر مبناي بهاي تمام شده اند ازه گیری می شود . مخارج بعدی مرتبط با دارایی ها ی ثابت مشهود که موجب بهبود و ضعیت د ارا یی در مقا یسه با استاند ارد عملکرد ارزیابی شده اولیه آن گردد ومنجر به افزایش منافع اقتصادی حاصل از دارایی شود ، به مبلغ دفتری دارایی اضافه و طی عمر مفید باقیمانده دارایی های مربوط مستهلک می شود . مخارج روزمره تعمیر و نگهداری دارایی ها که به منظور حفظ وضعیت دارایی درمقایسه با استاندارد عملکرد ارزیابی شده اولیه دارایی انجام می شود ، در زمان و قو ع به عنوان هزينه‌شناسایی مي‌گردد.
A42: 7

Sheet 7ادامه
A1: شرکت داروسازی خوارزمی (سهامی خاص)
A2: یادداشتهای توضیحی صورت های مالی
A3: =سودوزيان!A3 -> سال مالی منتهی به 30 اسفند 1403
A5: 3-5-2- استهلاك دارايي هاي ثابت مشهود، باتوجه به الگوی مصرف منافع اقتصادی آتی مورد انتظار (شامل عمر مفید بر آوردی)
A6: دارایی های مربوط و با در نظر گرفتن قانون جدید ماده 149 اصلاحیه قانون مالياتهاي مستقيم مصوب 94/04/21 و
A7: براساس نرخها و روشهاي زير محاسبه مي‌شود:
B8: نوع دارایی | D8: نرخ استهلاك | F8: روش استهلاك
B9: ساختمان | D9: 25ساله | F9: مستقيم
B10: تأسيسات | D10: 0.08 | F10: نزولي
B11: ماشين آلات | D11: 10 ساله | F11: مستقيم
B12: اثاثه و منصوبات | D12: 10 ساله | F12: مستقيم
B13: ابزارآلات | D13: 4 ساله | F13: مستقيم
B14: قالبها | D14: 4 ساله | F14: مستقيم
B15: وسايل نقليه | D15: 25، 35 درصد | F15: نزولي
B16: لوازم آزمايشگاهي | D16: 0.1 | F16: نزولي
A17: 3-5-3- براي داراييهاي ثابتي كه طي ماه تحصيل مي‌شود و مورد بهره ‌برداري قرار مي‌گيرد ، استهلاك از اول ماه بعد محاسبه
A18: و در حسابها منظور مي‌شود. در مواردي كه هريك از داراييهاي استهلاك‌پذير پس از آمادگي جهت بهره‌برداري به علت
A19: تعطيل كار يا علل ديگر براي مدتي مورد استفاده قرار نگيرد، ميزان استهلاك آن براي مدت ياد شده معادل 30% نرخ
A20: استهلاك منعکس در جدول بالا ست.
A21: 3-6- ذخيرة مزاياي پايان خدمت كاركنان
A22: ذخيرة مزاياي پايان خدمت كاركنان بر اساس يك ماه آخرين حقوق ثابت و مزاياي مستمر براي هر سال خدمت آنان محاسبه و
A23: درحسابها منظور مي شود.
A24: 3-7-درآمد عملیاتی
A25: درآمد عملیاتی به ارزش منصفانه مابه ازای دریافتی یا دریافتنی وبه کسر مبالغ برآوردی از بابت برگشت ازفروش و تخفیفات
A26: اندازه گیری می شود.
A27: 3-7-1-درآمد عملیاتی حاصل از فروش کالا در زمان تحویل کالا به مشتری شناسایی می شود.
A28: 3-7-2-درآمد ارائه خدمات ، در زمان ارائه خدمات ، شناسایی می شود.
... A51: هیات مدیره با بررسی نگهداشت سرمایه و نقدینگی سرمایه و نقدینگی مورد نیاز ، قصد نکهداری سرمایه گذاری های بلند مدت برای مدت طولانی را دارد .این سرمایه گذاری های به قصد استفاده مستمر توسط شرکت نگهداری می شود و هدف آن نگهداری پرتفویی از سرمایه گذاری ها جهت تامین درآمد و یا رشد سرمایه گذاری برای شرکت است .
A52: 8

Sheet 5
A1: شرکت داروسازی خوارزمی (سهامی خاص)
A2: =تاريخچه!A2 -> يادداشتهاي توضيحي صورتهاي مالي | B2: =#REF! -> #REF!
A3: =سودوزيان!A3 -> سال مالی منتهی به 30 اسفند 1403 | B3: =#REF! -> #REF!
A4: 5-درآمدهاي عملياتي
E5: یادداشت | H5: 1403 | L5: 1402
H6: ريال | L6: ريال
B7: فروش خالص:
C8: داخلی:
D9: فروش ناخالص داخلی | E9: 1_5 | H9: =H29 -> 10916820404618 | L9: =L29 -> 9537785823292 | R9: =H9=H29 -> TRUE | S9: =L9=L29 -> TRUE
D10: فروش ناخالص صادراتی | E10: 2_5 | H10: =H39 -> 353451928071 | L10: =L39 -> 270633805359 | R10: =H10=H39 -> TRUE | S10: =L10=L39 -> TRUE
D11: فروش ناخالص | H11: =SUM(H9:H10) -> 11270272332689 | L11: =SUM(L9:L10) -> 9808419628651
D12: برگشت از فروش و تخفیفات داخلی | E12: 3_5 | H12: =H50*-1 -> -3438799588956 | L12: =L50*-1 -> -1856000581953 | R12: =H12=-H50 -> TRUE | S12: =L12=-L50 -> TRUE
D13: تخفیفات صادراتی | E13: 4_5 | H13: =H60*-1 -> -2.1097472e+11 | L13: =L60*-1 -> -103668967444 | R13: =H13=-H60 -> TRUE | S13: =L13=-L60 -> TRUE
D14: فروش خالص | H14: =SUM(H11:H13) -> 7.620498e+12 | L14: =SUM(L11:L13) -> 7848750079254
D15: خدمات کارمزدی | E15: 5_5 | H15: 168819820716 | L15: 69574099716 | R15: =H16=-H71 -> TRUE
D16: تخفیفات کارمزدی | E16: 6_5 | H16: =H71*-1 -> -9101038809 | L16: 0
H17: =SUM(H14:H16) -> 7.7802168e+12 | L17: =SUM(L14:L15) -> 7918324178970 | N17: =H17-سودوزيان!F9 -> 0 | O17: =L17-سودوزيان!H9 -> 0 | R17: =سودوزيان!F9=H17 -> TRUE | S17: =L17=سودوزيان!H9 -> TRUE
D20: 5-1- فروش ناخالص محصولات داخلی شامل اقلام زير مي باشد:
F21: تعداد | H21: 1403 | J21: تعداد | L21: 1402 | R21: =H10+H13 -> 1.4247721e+11 | S21: =L10+L13 -> 166964837915
H22: ريال | L22: ريال | R22: =H10+H13-'5-5'!E50 -> 0.3531189
D23: فروش قرص | F23: 12193272 | H23: 4501601456581 | J23: 8313802 | L23: 3637415516484
D24: فروش شربت | F24: 20808008 | H24: 3695271386635 | J24: 29210517 | L24: 4057086082460 | R24: =L10+L13 -> 166964837915
D25: فروش قطره | F25: 11021626 | H25: 1956051141522 | J25: 10237864 | L25: 1254682988050
D26: فروش کپسول | F26: 327269 | H26: 181078629154 | J26: 674600 | L26: 234856678390
D27: فروش اسپري | F27: 1661451 | H27: 569014159580 | J27: 1404806 | L27: 339148019908
D28: فروش پماد | F28: 147893 | H28: 13803631146 | J28: 177232 | L28: 14596538000
H29: =SUM(H23:H28) -> 10916820404618 | L29: =SUM(L23:L28) -> 9537785823292 | N29: =H29-H9 -> 0 | O29: =L29-L9 -> 0
D31: 5-2- فروش ناخالص محصولات صادراتی شامل اقلام زير مي باشد:
F32: تعداد | H32: 1403 | J32: تعداد | L32: 1402
H33: ريال | L33: ريال
D34: فروش قرص | F34: 634329 | H34: 168996462220 | J34: 278397 | L34: 62495538540
D35: فروش شربت | F35: 330619 | H35: 78422396937 | J35: 900662 | L35: 124340785307
D36: فروش قطره | F36: 545123 | H36: 47399574100 | J36: 1114320 | L36: 82868861300
D37: فروش کپسول | F37: 121000 | H37: 26375582500 | J37: 437 | L37: 928620212
D38: فروش اسپري | F38: 80040 | H38: 32257912314 | J38: - | L38: 0
H39: =SUM(H34:H38) -> 353451928071 | L39: =SUM(L34:L38) -> 270633805359 | N39: =H39-H10 -> 0 | O39: =L39-L10 -> 0
D41: 5-3-برگشت از فروش و تخفيفات داخلی شامل اقلام زير مي باشد.
H42: 1403 | L42: 1402
H43: ريال | L43: ريال
D44: تخفيفات و برگشت از فروش قرص | H44: 1623225011135 | L44: 646999538054
...

Sheet 5-5
A1: شرکت داروسازی خوارزمی(سهامی خاص)
A2: =تاريخچه!A2 -> يادداشتهاي توضيحي صورتهاي مالي | B2: =#REF! -> #REF!
A3: =سودوزيان!A3 -> سال مالی منتهی به 30 اسفند 1403 | B3: =#REF! -> #REF!
B8: 5-7-خالص درآمد عملیاتی به تفکیک وابستگی اشخاص:
E9: 1403 | I9: 1402
E10: درآمد عملیاتی | G10: درصد نسبت به کل | I10: درآمد عملیاتی | K10: درصد نسبت به کل
E11: ريال | I11: ريال
C12: اشخاص وابسته | E12: =5069706404634-1851134270372-47423060382 -> 3171149073880 | G12: =E12/E14*100 -> 40.759135 | I12: 3175532884389 | K12: =I12/I14*100 -> 40.103598 | N12: =E12-'5-10'!F9 -> -1898557330754 | O12: =N12-'5'!H12 -> 1540242258202
C13: سایر مشتریان | E13: =سودوزيان!F9-'5-5'!E12 -> 4.6090677e+12 | G13: =E13/E14*100 -> 59.240865 | I13: 4742791294581 | K13: =I13/I14*100 -> 59.896402 | O13: =N12/'5'!H12 -> 0.55209886
E14: =SUM(E12:E13) -> 7.7802168e+12 | G14: =SUM(G12:G13) -> 100 | I14: =SUM(I12:I13) -> 7918324178970 | K14: =SUM(K12:K13) -> 100 | N14: =E14-'5'!H17 -> 0 | P14: =E14='5'!H17 -> TRUE | Q14: =I14='5'!L17 -> TRUE
B16: 5-7-1- در سال مورد گزارش مبلغ 3،171،149 میلیون ریال فروش شرکت به دارو سازان التیام بوده است که تماما به ارزش منصفانه در دفاتر منعکس گردیده است.
B18: 5-8- | C18: جدول مقایسه ای درآمدهای عملیاتی و بهای تمام شده فروش داخلی:
E19: 1403 | M19: 1402
E20: درآمد عملیاتی | G20: بهای تمام شده | I20: سود ناخالص | K20: درصد سود ناخالص به درآمد عملیاتی | M20: درصد سود ناخالص به درآمد عملیاتی | O20: كنترل
E21: ريال | G21: ريال | I21: ريال | O21: ='5'!#REF!-'5-5'!E29 -> #REF! | P21: ='6'!K29-'5-5'!G29 -> #REF! | Q21: =سودوزيان!F11-'5-5'!I29 -> -2.1391076e+11
C22: فروش خالص:
C23: قرص | E23: 2878376445446 | G23: 2308026557840 | I23: =E23-G23 -> 570349887606 | K23: =I23/E23*100 -> 19.814986 | M23: 36
C24: شربت | E24: 2543538915017 | G24: 1610337864276 | I24: =E24-G24 -> 933201050741 | K24: =I24/E24*100 -> 36.689081 | M24: 51
C25: قطره | E25: 1482366306136 | G25: 837885110608 | I25: =E25-G25 -> 644481195528 | K25: =I25/E25*100 -> 43.476514 | M25: 42
C26: کپسول | E26: 113790517570 | G26: 116483865022 | I26: =E26-G26 -> -2693347452 | K26: =I26/E26*100 -> -2.3669349 | M26: -24
C27: اسپری | E27: 447511078301 | G27: 274198480069 | I27: =E27-G27 -> 173312598232 | K27: =I27/E27*100 -> 38.728113 | M27: -162
C28: پماد | E28: 12437553192 | G28: 3780192600 | I28: =E28-G28 -> 8657360592 | K28: =I28/E28*100 -> 69.606622 | M28: 40
E29: =SUM(E23:E28) -> 7478020815662 | G29: =SUM(G23:G28) -> 5150712070415 | I29: =SUM(I23:I28) -> 2327308745247 | K29: =I29/E29*100 -> 31.121988 | M29: 41 | O29: =E29='5'!H9+'5'!H12 -> TRUE
C34: خدمات کارمزدی | E34: 159718781907 | G34: 196307563357 | I34: =E34-G34 -> -36588781450 | K34: =I34/E34 -> -0.22908252 | M34: 0.1 | O34: =E34='5'!H15+'5'!H16 -> TRUE
E36: =E29+E34 -> 7637739597569 | G36: =G29+G34+G33+G32+G31 -> 5347019633772 | I36: =E36-G36 -> 2290719963797 | K36: =I36/E36 -> 0.29992119 | M36: 0.4
N37: =E29-'5'!H9-'5'!H12 -> 0
B38: 5-9- | C38: جدول مقایسه ای درآمدهای عملیاتی و بهای تمام شده فروش صادراتي:
E40: 1403 | M40: 1402
E41: درآمد عملیاتی | G41: بهای تمام شده | I41: سود ناخالص | K41: درصد سود ناخالص به درآمد عملیاتی | M41: درصد سود ناخالص به درآمد عملیاتی | N41: =G36+G50 -> 5666818827105 | O41: ='6-1'!I34 -> 5666818827105
E42: ريال | G42: ريال | I42: ريال | O42: =O41-N41 -> 0
C43: فروش خالص: | I43: =G43-E43 -> 0
C44: قرص | E44: 70585251315 | G44: 178972628147 | I44: =E44-G44 -> -108387376832 | K44: =I44/E44*100 -> -153.55528 | M44: -14
C45: شربت | E45: 33631800393 | G45: 73666440249 | I45: =E45-G45 -> -40034639856 | K45: =I45/E45*100 -> -119.03805 | M45: -37
C46: قطره | E46: 17978290081 | G46: 33980568775 | I46: =E46-G46 -> -16002278694 | K46: =I46/E46*100 -> -89.008903 | M46: -22
C47: کپسول | E47: 8769651526 | G47: 17754058173 | I47: =E47-G47 -> -8984406647 | K47: =I47/E47*100 -> -102.44884 | M47: -1
C48: اسپری | E48: 11512219291 | G48: 15425497989 | I48: =E48-G48 -> -3913278698 | K48: =I48/E48*100 -> -33.992392 | M48: 0
C49: پماد | E49: 0 | G49: 0 | I49: =E49-G49 -> 0 | K49: 0
E50: =SUM(E44:E49) -> 142477212606 | G50: =SUM(G44:G49) -> 319799193333 | I50: =SUM(I44:I49) -> -177321980727 | K50: =I50/E50*100 -> -124.45638 | M50: -26
N51: =N50-E50 -> -142477212606
A53: 10
...

Sheet 6
A1: شرکت داروسازی خوارزمی (سهامی خاص)
A2: =#REF! -> #REF!
A3: =سودوزيان!A3 -> سال مالی منتهی به 30 اسفند 1403
A4: 6- | B4: بهای تمام شده درآمدهای عملیاتی
E5: 1400 | M5: 1399
C6: یادداشت
E7: تولیدی | G7: بازرگانی | I7: ارائه خدمات | K7: جمع | M7: تولیدی | O7: بازرگانی | Q7: ارائه خدمات | S7: جمع
E8: ریال | G8: ریال | I8: ریال | K8: ریال | M8: ریال | O8: ریال | Q8: ریال | S8: ریال
B9: مواد مستقیم | C9: 6_1 | D9: =(E9-M9)/M9*100 -> 8.2192001 | E9: =E51 -> 2201052765346 | K9: =I9+E9 -> 2201052765346 | M9: 2.0338838e+12 | Q9: 3189103298 | S9: =SUM(M9:R9) -> 2.0370729e+12
B10: دستمزد مستقیم | C10: 6_3 | D10: =(E10-M10)/M10*100 -> #REF! | E10: ='6-2'!#REF! -> #REF! | I10: 0 | K10: =I10+E10 -> #REF! | M10: 1.2635901e+11 | Q10: 1.1542658e+09 | S10: =SUM(M10:R10) -> 127513277836
B11: سربار ساخت: | K11: =I11+E11 -> 0
B12: دستمزد ومزایا وامکانات رفاهی پرسنل | D12: =(E12-M12)/M12*100 -> 70.928916 | E12: 245613900788 | K12: =I12+E12 -> 245613900788 | M12: 143693592999 | S12: =SUM(M12:R12) -> 143693592999
B13: استهلاک | D13: =(E13-M13)/M13*100 -> 83.718144 | E13: 65298093724 | K13: =I13+E13 -> 65298093724 | M13: 35542539431 | S13: =SUM(M13:R13) -> 35542539431
B14: تعمیر ونگهداری | D14: =(E14-M14)/M14*100 -> 59.604418 | E14: 65074844649 | K14: =I14+E14 -> 65074844649 | M14: 40772583472 | S14: =SUM(M14:R14) -> 40772583472
B15: اجاره انبار واجاره وسایل نقلیه | D15: =(E15-M15)/M15*100 -> 92.399748 | E15: 21832779781 | K15: =I15+E15 -> 21832779781 | M15: 11347613515 | S15: =SUM(M15:R15) -> 11347613515
B16: آب ، برق ، تلفن و سوخت | D16: =(E16-M16)/M16*100 -> 97.090505 | E16: 9144663891 | K16: =I16+E16 -> 9144663891 | M16: 4639829756 | S16: =SUM(M16:R16) -> 4639829756
B17: ملزومات مصرفی | D17: =(E17-M17)/M17*100 -> 337.03933 | E17: 63535544907 | K17: =I17+E17 -> 63535544907 | M17: 14537717810 | S17: =SUM(M17:R17) -> 14537717810
B18: سایر موارد | D18: =(E18-M18)/M18*100 -> 78.609451 | E18: 152609681173 | K18: =I18+E18 -> 152609681173 | M18: 85443228320 | S18: =SUM(M18:R18) -> 85443228320
D19: 55 | E19: =SUM(E12:E18) -> 623109508913 | G19: =SUM(G12:G18) -> 0 | I19: =SUM(I12:I18) -> 0 | K19: =SUM(K12:K18) -> 623109508913 | M19: =SUM(M12:M18) -> 335977105303 | Q19: =SUM(Q12:Q18) -> 0 | S19: =SUM(S12:S18) -> 335977105303 | AB19: =Y19-S19 -> -335977105303
B20: هزینه های جذب نشده
B21: جمع هزینه های ساخت | E21: =E19+E10+E9 -> #REF! | I21: =I19+I10+I9 -> 0 | K21: =K19+K10+K9 -> #REF! | M21: =M19+M10+M9 -> 2.4962199e+12 | Q21: =Q19+Q10+Q9 -> 4.3433691e+09 | S21: =S19+S10+S9 -> 2.5005633e+12
B22: (افزایش) کاهش موجودی های در جریان ساخت | E22: ='15-16'!#REF!-'15-16'!L72 -> #REF! | K22: =I22+E22 -> #REF! | M22: -2.7735216e+10 | S22: =Q22+M22 -> -2.7735216e+10
B23: ضایعات غیر عادی | E23: 0 | K23: =I23+E23 -> 0 | M23: -8100549373 | S23: =M23+Q23 -> -8100549373
B24: بهای تمام شده ساخت | E24: =SUM(E21:E23) -> #REF! | G24: =SUM(G21:G23) -> 0 | I24: =SUM(I21:I23) -> 0 | K24: =SUM(K21:K23) -> #REF! | M24: =SUM(M21:M23) -> 2.4603841e+12 | Q24: =SUM(Q21:Q23) -> 4.3433691e+09 | S24: =SUM(S21:S23) -> 2.4647275e+12
B25: محصول خریداری شده | G25: 4152000000 | K25: =G25 -> 4152000000 | S25: 0
B26: (افزایش) کاهش موجودی های ساخته شده | E26: ='15-16'!#REF!-'15-16'!L71+2927040000 -> #REF! | G26: =-2927040000 -> -2927040000 | I26: 0 | K26: =E26+I26+G26 -> #REF! | M26: -313834694078 | Q26: 0 | S26: =M26+Q26 -> -313834694078
B27: سایر | E27: 0 | G27: 0 | I27: 0 | K27: =E27+I27+G27 -> 0 | M27: -48863021203 | Q27: 0 | S27: =M27+Q27 -> -48863021203
B28: بهای تمام شده مواد و ملزومات فروش رفته | C28: 6_4 | G28: 33466315354 | K28: =E28+I28+G28 -> 33466315354 | S28: 0
E29: =SUM(E24:E28) -> #REF! | G29: =SUM(G24:G28) -> 34691275354 | I29: =SUM(I24:I28) -> 0 | K29: =SUM(K24:K28) -> #REF! | M29: =SUM(M24:M27) -> 2.0976864e+12 | O29: =SUM(O24:O28) -> 0 | Q29: =SUM(Q24:Q27) -> 4.3433691e+09 | S29: =SUM(S24:S27) -> 2.1020298e+12
A32: 6-1- | B32: گردش مواد به شرح ذیل می باشد
E33: سال1400 | G33: سال1399
E34: ریال | G34: ریال
B35: موجودی کالای ابتدای دوره | E35: 1116656059148 | G35: 557193857105 | I35: =E35+G40 -> -120
B36: خرید طی دوره | E36: 2169035754939 | G36: 2623039548389
B37: سایر وارده ها (امانی) | E37: 165435492 | G37: 0
B38: کسر و اضافه انبار | E38: 109019574 | G38: 0
B39: آماده برای تولید | E39: =SUM(E35:E38) -> 3285966269153 | G39: =SUM(G35:G38) -> 3180233405494
B40: موجودی کالای پایان دوره | E40: -1041781676935 | G40: -1116656059268
B41: فروش طی دوره | E41: -31958515307 | G41: -18856771237
B42: کسر و اضافه انبار | E42: 0
...

Sheet 5-10
A1: شرکت داروسازی خوارزمی (سهامی خاص)
A2: یادداشت های توضیحی صورتهای مالی
A3: سال مالی منتهی به 30 اسفند 1403
B5: 5-10- | C5: فروش ناخالص داخلی به تفکیک مشتری:
F6: 1403 | H6: 1402
F7: ريال | H7: ريال
C8: اشخاص وابسته:
C9: شرکت داروسازان التیام | F9: 5069706404634 | H9: 4024760946522
C10: سایر اشخاص:
C11: شرکت پخش البرز | F11: 1152498247480 | H11: 769807064268
C12: شرکت پخش هجرت | F12: 932005817426 | H12: 592260677101
C13: شرکت پخش سراسری یارا طب ثامن | F13: 611233997615 | H13: 316637661472
C14: پخش دایا دارو | F14: 603987158023 | H14: 427270787256
C15: شرکت پخش قاسم ایران | F15: 475469527079 | H15: 274812902697
C16: بهستان پخش | F16: 444544746100 | H16: 540276406680
C17: شرکت سلامت پخش هستی | F17: 374083905777 | H17: 503991934801
C18: شرکت پخش محیا دارو | F18: 274297955557 | H18: 102080231229
C19: پخش سراسری ممتاز | F19: 190388915504 | H19: 394618147420
C20: شرکت پخش رازی | F20: 111589949210 | H20: 632770080027
C21: شرکت پخش فردوس | F21: 93163750474 | H21: 245167987073
C22: دارو گستر طوبی | F22: 36033712300 | H22: 148021747500
... C24: سایر | F24: 543066317439 | H24: 44242365765
F25: =SUM(F9:F24) -> 10916820404618 | H25: =SUM(H9:H24) -> 9537785823292 | L25: =F25='5'!H9 -> TRUE | M25: =H25='5'!L9 -> TRUE
B27: 5-11-جدول فروش خالص صادراتی به تفکیک گروه کالایی و کشور: | F27: 1403 | H27: 1402
B29: ردیف | C29: نام شرکت | D29: کشور | E29: گروه کالا | F29: مبلغ ریالی | H29: مبلغ ریالی
B30: 1 | C30: نوین فارما لیمیتد | D30: افغانستان | E30: قرص | F30: 69137337062 | H30: 13390197774
E31: شربت | F31: 17769033139 | H31: 51478609622
E32: قطره | F32: 18110887000 | H32: 51903461038
E33: کپسول | F33: 12729772992 | H33: 0
E34: اسپری | F34: 5823790100 | H34: 0
B35: 2 | C35: شرکت دارویی امین اعلاء | D35: سومالی | E35: قرص | F35: 6586774620 | H35: 4031300000
E36: شربت | F36: 7956946593 | H36: 16266735000
E37: قطره | F37: 337805000 | H37: 900000000
E38: کپسول | F38: 6756100 | H38: 0
B39: 3 | C39: شرکت تامیریس (آقای موتولو مجیداف) | D39: تاجیکستان | E39: قرص | F39: 0 | H39: 12370946481
E40: شربت | F40: 0 | H40: 2970915000
E41: قطره | F41: 0 | H41: 1108025000
B42: 4 | C42: TEC PHARMA SPAIN | D42: اسپانیا | E42: قرص | F42: 4018110000 | H42: 0
B43: 5 | C43: Achi Drugstore | D43: سوریه | E43: کپسول | F43: 0 | H43: 389008000
B44: 6 | C44: SA VIOURS PHARMA | D44: اربیل-عراق | E44: قرص | F44: 0 | H44: 12155640000
...

Sheet 6-1
A1: شرکت داروسازی خوارزمی (سهامی خاص)
A2: يادداشتهاي توضيحي صورت هاي مالي
A3: سال منتهی به 30 اسفند1403
A4: 6- | B4: بهای تمام شده درآمدهای عملیاتی
C5: یادداشت | I5: 1403 | K5: 1402
I6: ریال | K6: ریال
B7: مواد مستقیم | C7: 6_1 | I7: 3254533296155 | K7: 3895387018547
B8: دستمزد مستقیم | C8: 6-2 | I8: 346380535332 | K8: 319047792173
B9: کارمزد پیمانکاری | I9: 2614590000 | K9: 3521936000
B10: سربار ساخت:
B11: دستمزد | I11: 459974821773 | K11: 412826438821
B12: ایاب ذهاب کارکنان | I12: 116374132011 | K12: 5.4692436e+10
B13: بیمه سهم کارفرما | I13: 106609412986 | K13: 7.3385161e+10
B14: تعمیر ونگهداری | I14: 105980185665 | K14: 1.7063292e+11
B15: استهلاک | I15: 61414443701 | K15: 6.1158221e+10
B16: باز خرید سنوات | I16: 59130201818 | K16: 4.3153377e+10
B17: ملزومات مصرفی | I17: 57036224299 | K17: 88580341455
B18: اجاره انبار واجاره وسایل نقلیه | I18: 36462987564 | K18: 2.0030829e+10
B19: عیدی | I19: 32298533984 | K19: 2.7519056e+10
B20: آب ، برق ، تلفن و سوخت | I20: 19265148322 | K20: 8.8997306e+09
B21: غذای کارکنان | I21: 14091716537 | K21: 2.2740376e+10
B22: هزینه های حقوقی و ثبتی | C22: 6-3 | I22: 11725587499 | K22: 1.1256709e+10
B23: خدمات اینترنتی و پشتیبانی سیستمهای نرم افزاری | I23: 10609569258 | K23: 1.2470978e+10
B24: کمکهای غیر نقدی | I24: 14333128166 | K24: 6.513397e+10
B25: تحقیقات ، آزمایشات و مواد نمونه | I25: 4551638863 | K25: 1.3508234e+10
B26: سایر موارد | I26: 384045534755 | K26: 4.2026601e+11
I27: =SUM(I11:I26) -> 1493903267201 | K27: 1.5062548e+12
B28: جمع هزینه های ساخت | I28: =I7+I8+I27+I9 -> 5097431688688 | K28: 5.7242115e+12
B29: (افزایش) کاهش موجودی های در جریان ساخت | I29: 123223716589 | K29: -122094442860
B30: بهای تمام شده ساخت | I30: =SUM(I28:I29) -> 5220655405277 | K30: 5.6021171e+12
B31: محصول خریداری شده | I31: 0 | K31: 0
B32: (افزایش) کاهش موجودی های ساخته شده | I32: 482838095298 | K32: -729706068200
B33: سایر | I33: -36674673470 | K33: -29797003546
B34: بهای تمام شده مواد و ملزومات فروش رفته | I34: =SUM(I30:I33) -> 5666818827105 | K34: 4.842614e+12 | P34: =I34+سودوزيان!F10 -> 0 | Q34: =K34+سودوزيان!H10 -> 0
A46: 6-1- | B46: گردش مواد به شرح ذیل می باشد
I47: سال1403 | K47: سال1402
I48: ریال | K48: ریال
B49: موجودی کالای ابتدای دوره | I49: 1843044930332 | K49: 1118035649634
B50: خرید طی دوره | C50: 6-1-1 | I50: =E70 -> 2899918129650 | K50: 4658635344751
B51: کسر و اضافه انبار | I51: 288480655 | K51: -12496327
...

Sheet 6-2
A1: شرکت داروسازی خوارزمی (سهامی خاص)
A2: =تاريخچه!A2 -> يادداشتهاي توضيحي صورتهاي مالي
A3: =سودوزيان!A3 -> سال مالی منتهی به 30 اسفند 1403
A5: 6-2 | B5: اطلاعات مربوط به دستمزد مستقیم به شرح ذیل است:
E6: 1403 | G6: 1402
E7: ریال | G7: ریال
B8: حقوق و دستمزد ومزایا | E8: 262268051439 | G8: 255456225470
B9: بیمه سهم کارفرما وبیکاری | E9: 53210975697 | G9: 43626102625
B10: مزایای پایان خدمت کارکنان | E10: 30901508196 | G10: 19965464078
E11: =SUM(E8:E10) -> 346380535332 | G11: =SUM(G8:G10) -> 319047792173 | P11: =E11='6-1'!I8 -> TRUE | Q11: =G11='6-1'!K8 -> TRUE
A13: 6-2-1- | B13: افزایش هزينه حقوق و دستمزد مستقيم نسبت به سال 1402 ناشي از افزایش قانونی حقوق و دستمزد مي باشد
A15: 6-3 | B15: هزینه فوق بابت کارمزد بارگذاری مستندات قانونی محصولات تولید شده در هر بچ شامل کد IRC و XML در سامانه تی تک سازمان غذا و دارو می باشد.
A17: 6-4 | B17: ظرفیت اسمی و قابل دسترس:
B18: گروه محصولات | C18: واحد سنجش | D18: ظرفیت اسمی 3 شیفت | E18: ظرفیت اسمی 1 شیفت | G18: ظرفیت قابل دسترس | I18: تولید واقعی 1403 | K18: تولید واقعی 1402
B19: قرص | C19: عدد | D19: 2227100000 | E19: 742366667 | G19: 784067012 | I19: 540984437 | K19: 656013629
B20: شربت | C20: عدد | D20: 54000000 | E20: 18000000 | G20: 25676366 | I20: 19224894 | K20: 32222024
B21: قطره | C21: عدد | D21: 33000000 | E21: 11000000 | G21: 13272691 | I21: 9660374 | K21: 12580629
B22: اسپری | C22: عدد | D22: 4200000 | E22: 1400000 | G22: 1790056 | I22: 1681099 | K22: 1597454
B23: کپسول | C23: عدد | D23: 153000000 | E23: 51000000 | G23: 29466523 | I23: 4954501 | K23: 19134600
B24: جمع کل | C24: عدد | D24: =SUM(D19:D23) -> 2471300000 | E24: =SUM(E19:E23) -> 823766667 | G24: =SUM(G19:G23) -> 854272648 | I24: =SUM(I19:I23) -> 576505305
A26: 7- | B26: هزینه های فروش ، اداری و عمومی
C27: یادداشت | E27: 1403 | G27: 1402
E28: ریال | G28: ریال
B29: هزینه های فروش و توزیع:
B30: حقوق و دستمزد و مزایا | C30: 7-1 | E30: 318471463040 | G30: 2.2317027e+11
B31: بيمه سهم كارفرما وبيكاري | E31: 56975722143 | G31: 4.2274599e+10
B32: مزاياي پايان خدمت كاركنان | E32: 33559040495 | G32: 2.2197688e+10
B33: سایر مزایای کارکنان | C33: 7-2 | E33: 25319537483 | G33: 4.8884802e+10
B34: هزينه حق الزحمه خدمات | C34: 7-3 | E34: 22012510090 | G34: 1.0478428e+10
B35: استهلاک | C35: 7-4 | E35: 21592487958 | G35: 2.4029269e+10
B36: هدایا ، جوایز و تشویقات | E36: 18802544044 | G36: 6.6804081e+09
B37: هزینه بازاریابی وفروش | C37: 7-5 | E37: 12084808942 | G37: 3.2262843e+10
B38: سيستمهاي نرم افزاري | E38: 9053816723 | G38: 6.9705625e+09
B39: تعمير و نگهداري دارائيها | C39: 7-6 | E39: 8285862648 | G39: 1.9495885e+10
B40: ملزومات | C40: 7-7 | E40: 3368740126 | G40: 11510946574
B41: آگهي و تبليغات و نمايشگاه | E41: 2643343000 | G41: 4.7050066e+09
B42: اجاره محل | E42: 2552387436 | G42: 1.4021461e+09
B43: عوارض | E43: 2478206225 | G43: 2.4462215e+08
B44: نمونه و تحقیقات | E44: 1915300521 | G44: 1.7954666e+09
B45: حمل و نقل ترخیص و بارگیری | E45: 1887455845 | G45: 3.6504221e+09
...

Sheet 12
B1: شرکت داروسازی خوارزمی (سهامی خاص )
B2: يادداشتهاي توضيحي صورت هاي مالي
B3: =سودوزيان!A3 -> سال مالی منتهی به 30 اسفند 1403
B6: 12- | C6: دارایی های ثابت مشهود | I6: (مبالغ به ریال)
E7: زمین | G7: ساختمان | I7: لوازم آزمایشگاهی | K7: تاسیسات | M7: ماشین آلات و تجهیزات | O7: وسایل نقلیه | Q7: اثاثه و منصوبات | S7: ابزار آلات | U7: جمع | W7: دارایی های در جریان تکمیل | Y7: پیش پرداخت های سرمایه ای | AA7: موجودی دارائیهای ثابت نزد انبار | AC7: جمع
B8: بهای تمام شده یا مبلغ تجدید ارزیابی : | U8: =SUM(E8:S8) -> 0 | AC8: =SUM(U8:Y8) -> 0
B9: مانده در ابتدای سال 1399 | E9: 3370015495 | G9: 84952600561 | I9: 12033313081 | K9: 43836485039 | M9: 195941849441 | O9: 13661344455 | Q9: 55766662551 | S9: 9517820170 | U9: =SUM(E9:S9) -> 419080090793 | W9: 54464918803 | Y9: 19255023670 | AA9: 1120359836 | AC9: =SUM(U9:AA9) -> 493920393102
B10: افزایش | C10: افزایش | E10: 0 | G10: 0 | I10: 0 | K10: 0 | M10: 0 | O10: 0 | Q10: 0 | S10: 0 | U10: 0 | W10: 25695473261 | Y10: 129762465126 | AA10: 309339266 | AC10: =SUM(U10:AA10) -> 155767277653
B11: واگذار شده | C11: واگذار شده | E11: 0 | G11: 0 | I11: -166600000 | K11: 0 | M11: 0 | O11: -239570000 | Q11: 0 | S11: 0 | U11: =SUM(E11:S11) -> -406170000 | W11: -69233366 | Y11: 0 | AA11: 0 | AC11: =SUM(U11:AA11) -> -475403366
B12: سایر نقل و انتقالات و تغییرات | C12: سایر نقل و انتقالات و تغییرات | E12: 0 | G12: 0 | I12: 39758170033 | K12: 7007816863 | M12: 8352600000 | O12: 0 | Q12: 19263131502 | S12: 9478677332 | U12: =SUM(E12:S12) -> 83860395730 | W12: 0 | Y12: -103429335173 | AA12: 19568939443 | AC12: =SUM(U12:AA12) -> 0
B13: مانده در پایان سال 1399 | C13: =CONCATENATE("مانده در پایان سال"," ",#REF!) -> #REF! | E13: =SUM(E9:E12) -> 3370015495 | F13: =SUM(F9:F12) -> 0 | G13: =SUM(G9:G12) -> 84952600561 | H13: =SUM(H9:H12) -> 0 | I13: =SUM(I9:I12) -> 51624883114 | J13: =SUM(J9:J12) -> 0 | K13: =SUM(K9:K12) -> 50844301902 | L13: =SUM(L9:L12) -> 0 | ... AC13: =SUM(AC9:AC12) -> 649212267389
C14: کاهش | E14: 0 | F14: 0 | G14: 0 | H14: 0 | I14: 0 | J14: 0 | K14: 0 | L14: 0 | M14: 0 | N14: 0 | O14: 0 | P14: 0 | Q14: 0 | R14: 0 | S14: 0 | T14: 0 | U14: 0 | V14: 0 | W14: 0 | Y14: -11031978053 | AA14: 0 | AB14: 0 | AC14: 0
B15: افزایش | C15: افزایش | E15: 0 | G15: 0 | I15: 3021218572 | K15: 773200000 | M15: 51434571849 | O15: 0 | Q15: 53862573127 | S15: 18781679820 | U15: =SUM(E15:T15) -> 127873243368 | W15: =43759347036+669128102 -> 44428475138 | Y15: -11233132580 | AA15: 28076533810 | AC15: =AA15+Y14+W15+U15+Y15 -> 178113141683
B16: سایر نقل و انتقالات و تغییرات | C16: سایر نقل و انتقالات و تغییرات | E16: 0 | G16: 0 | I16: 0 | K16: 0 | M16: 0 | O16: 0 | Q16: 0 | S16: 0 | U16: =SUM(E16:T16) -> 0 | W16: 0 | AA16: 0 | AC16: 0
B17: مانده در پایان سال1400 | C17: =CONCATENATE("مانده در پایان سال"," ",#REF!) -> #REF! | E17: =SUM(E13:E16) -> 3370015495 | G17: =SUM(G13:G16) -> 84952600561 | I17: =SUM(I13:I16) -> 54646101686 | K17: =SUM(K13:K16) -> 51617501902 | M17: =SUM(M13:M16) -> 255729021290 | O17: =SUM(O13:O16) -> 13421774455 | Q17: =SUM(Q13:Q16) -> 128892367180 | S17: =SUM(S13:S16) -> 37778177322 | U17: =SUM(U13:U16) -> 630407559891 | W17: =SUM(W13:W16) -> 124519633836 | Y17: =SUM(Y13:Y15) -> 23323042990 | AA17: =AA13+AA15+AA16 -> 49075172355 | AC17: =SUM(AC13:AC16) -> 827325409072 | AF17: =SUM(AA15:AA16) -> 28076533810
A23: 15

Sheet 8.9.10.11
A1: شرکت داروسازی خوارزمی (سهامی خاص)
A2: =تاريخچه!A2 -> يادداشتهاي توضيحي صورتهاي مالي
A3: =سودوزيان!A3 -> سال مالی منتهی به 30 اسفند 1403
A6: 8- | B6: سایر درآمد ها
E7: یادداشت | G7: 1403 | I7: 1402
G8: ریال | I8: ریال
B9: سود ناشي ازتسعير دارائيها ارزي | G9: 22837331920 | I9: 22563104580
B10: اضافات انبارگردانی | G10: 1231277584 | I10: 46540077
B11: سایر | G11: 34230807 | I11: 17687916350
G12: =SUM(G9:G11) -> 24102840311 | I12: =SUM(I9:I11) -> 40297561007 | M12: =G12-سودوزيان!F13 -> 0 | O12: =G12=سودوزيان!F13 -> TRUE | P12: =I12=سودوزيان!H13 -> TRUE
A17: 9- | B17: سایر هزینه ها
E18: یادداشت | G18: 1403 | I18: 1402
G19: ریال | I19: ریال
B20: هزینه مابه التفاوت ارز ترجیجی مربوط به صادرات | E20: 9-1 | G20: 2286738763 | I20: 0
B21: هزینه شناسایی جریمه مالیاتی ماده169سال97و98 | G21: 2789773140 | I21: 0
B22: هزینه شناسایی سه در هزار اتاق بازرگانی | G22: 27740120222 | I22: 0
B23: سایر | G23: =1406364+189549923 -> 190956287 | I23: 0
G24: =SUM(G20:G23) -> 33007588412 | I24: =SUM(I20:I23) -> 0 | M24: =G24+سودوزيان!F14 -> 0 | O24: =I24+سودوزيان!H14 -> 0
A26: 9-1- | B26: مبلغ فوق بابت پرداخت مابه التفاوت ارز ترجیحی محصول صادراتی قرص آزیترومایسین500و250میلی گرم به کشور افغانستان بوده که به حساب خزانه داری کل کشور واریز گردیده است.
A28: 10- | B28: هزینه های مالی
G29: 1403 | I29: 1402
G30: ریال | I30: ریال
B31: سود تسهيلات دريافتي | G31: 176333487657 | I31: 270926966935
B32: كارمزد و دير كرد اقساط وام | G32: 174122614405 | I32: 97301782293
G33: =SUM(G31:G32) -> 350456102062 | I33: =SUM(I31:I32) -> 368228749228 | M33: =G33+سودوزيان!F16 -> 0 | O33: =I33+سودوزيان!H16 -> 0
A35: 11- | B35: سایر درآمد ها و هزینه های غیر عملیاتی
G36: 1403 | I36: 1402
G37: ریال | I37: ریال
B38: سود حاصل از سپرده های سرمایه گذاری بانکی | G38: 23353106087 | I38: 5455478663
B39: سود حاصل از فروش مواداولیه و... | E39: 11-1 | G39: =39355153766-22297152857 -> 17058000909 | I39: 6475931469
B40: فروش ضایعات بسته بندی | G40: 0 | I40: 459411877
B41: سود سهام | G41: 0 | I41: 912240000
B42: سایر | G42: 3075039006 | I42: 616534115
G43: =SUM(G38:G42) -> 43486146002 | I43: =SUM(I38:I42) -> 13919596124 | M43: =G43-سودوزيان!F17 -> 0 | O43: =I43-سودوزيان!H17 -> 0
A45: 11-1- | B45: مبلغ سودحاصل ازفروش مواد اولیه و.... تهاتر مبلغ 39،355،153،766 ريال فروش مواد اوليه و ملزومات و مبلغ 22،297،152،857 ريال بهاي تمام شده كالاي فروش رفته مواد اوليه و ملزومات می باشد.
A50: 14

Sheet 12 اصلی
B1: شرکت داروسازی خوارزمی (سهامی خاص )
B2: يادداشتهاي توضيحي صورت هاي مالي
B3: سال مالی منتهی به30اسفند1403
B6: 12- | C6: دارایی های ثابت مشهود | I6: (مبالغ به ریال)
E7: زمین | G7: ساختمان | I7: لوازم آزمایشگاهی | K7: تاسیسات | M7: ماشین آلات و تجهیزات | O7: وسایل نقلیه | Q7: اثاثه و منصوبات | S7: ابزار آلات | U7: جمع | W7: دارایی های در جریان تکمیل | Y7: پیش پرداخت های سرمایه ای | AA7: موجودی دارائیهای ثابت نزد انبار | AC7: جمع
B8: بهای تمام شده : | U8: =SUM(E8:S8) -> 0 | AC8: =SUM(U8:Y8) -> 0
B9: مانده ابتدای سال 1402 | E9: 3370015495 | G9: 195854099401 | I9: 54855333686 | K9: 72280045586 | M9: 297295066342 | O9: 13421774455 | Q9: 130898436298 | S9: 53429691934 | U9: 821404463197 | W9: 0 | Y9: 12388796860 | AA9: 0 | AC9: 833793260057
B10: افزایش | C10: افزایش | E10: 0 | G10: 0 | I10: 3380000000 | K10: 12483564312 | M10: 11583735925 | O10: 0 | Q10: 10671458657 | S10: 18213846580 | U10: 56332605474 | W10: 0 | Y10: 0 | AA10: 0 | AC10: 56332605474
B11: سایر نقل و انتقالات | C11: سایر نقل و انتقالات و تغییرات | E11: 0 | G11: 0 | I11: 0 | K11: 0 | M11: 0 | O11: 0 | Q11: 0 | S11: 0 | U11: 0 | W11: 0 | Y11: 0 | AA11: =AA9*-1 -> 0 | AC11: =SUM(U11:AA11) -> 0
B12: مانده پایان سال1402 | C12: =CONCATENATE("مانده در پایان سال"," ",#REF!) -> #REF! | E12: =SUM(E9:E11) -> 3370015495 | G12: =SUM(G9:G11) -> 195854099401 | I12: =SUM(I9:I11) -> 58235333686 | K12: =SUM(K9:K11) -> 84763609898 | M12: =SUM(M9:M11) -> 308878802267 | O12: =SUM(O9:O11) -> 13421774455 | Q12: =SUM(Q9:Q11) -> 141569894955 | S12: =SUM(S9:S11) -> 71643538514 | U12: =SUM(U9:U11) -> 877737068671 | W12: =SUM(W9:W11) -> 0 | Y12: =SUM(Y9:Y11) -> 12388796860 | AA12: 0 | AC12: =SUM(AC9:AC11) -> 890125865531
C13: کاهش | E13: 0 | G13: 0 | I13: 0 | K13: 0 | M13: 0 | O13: 0 | Q13: 0 | S13: 0 | U13: =SUM(G13:S13) -> 0 | W13: 0 | Y13: . | AA13: 0 | AC13: =SUM(U13:AA13) -> 0
B14: افزایش | C14: افزایش | E14: 0 | G14: 0 | I14: 27400000 | K14: 5382730000 | M14: 4555152550 | O14: 0 | Q14: =1468958636-21207440 -> 1447751196 | S14: 18714656573 | U14: =SUM(E14:S14) -> 30127690319 | W14: 0 | Y14: 3402594940 | AA14: 0 | AC14: =SUM(U14:AA14) -> 33530285259
B15: سایر نقل و انتقالات و تغییرات | C15: سایر نقل و انتقالات و تغییرات | E15: 0 | G15: 0 | I15: 0 | K15: 0 | M15: 0 | O15: 0 | Q15: 0 | S15: 0 | U15: =SUM(E15:S15) -> 0 | W15: 0 | AA15: 0 | AC15: =SUM(U15:AA15) -> 0
B16: سایر نقل و انتقالات | C16: سایر نقل و انتقالات و تغییرات | E16: 0 | G16: 0 | I16: 0 | K16: 0 | M16: 0 | O16: 0 | Q16: 0 | S16: 0 | U16: =SUM(E16:S16) -> 0 | W16: 0 | Y16: 0 | AA16: 0 | AC16: =SUM(U16:AA16) -> 0
B17: مانده پایان سال1403 | C17: =CONCATENATE("مانده در پایان سال"," ",#REF!) -> #REF! | E17: =SUM(E12:E16) -> 3370015495 | G17: =SUM(G12:G16) -> 195854099401 | I17: =SUM(I12:I16) -> 58262733686 | K17: =SUM(K12:K16) -> 90146339898 | M17: =SUM(M12:M16) -> 313433954817 | O17: =SUM(O12:O16) -> 13421774455 | Q17: =SUM(Q12:Q16) -> 143017646151 | S17: =SUM(S12:S16) -> 90358195087 | U17: =SUM(U12:U16) -> 907864758990 | W17: =SUM(W12:W16) -> 0 | Y17: =SUM(Y12:Y16) -> 15791391800 | AA17: =SUM(AA12:AA16) -> 0 | AC17: =SUM(AC12:AC16)-1 -> 923656150789
A22: 15

Sheet 12-1
A1: شرکت داروسازی خوارزمی (سهامی خاص)
A2: =تاريخچه!A2 -> يادداشتهاي توضيحي صورتهاي مالي
A3: =سودوزيان!A3 -> سال مالی منتهی به 30 اسفند 1403
V5: (مبالغ به ریال)
D6: زمین | F6: ساختمان | H6: لوازم آزمایشگاهی | J6: تاسیسات | L6: ماشین آلات و تجهیزات | N6: وسایل نقلیه | P6: اثاثه و منصوبات | R6: ابزار آلات | T6: جمع | V6: دارایی های در جریان تکمیل | X6: پیش پرداخت های سرمایه ای | Z6: موجودی دارائیهای ثابت نزد انبار | AB6: جمع
B7: استهلاك انياشته:
B8: مانده در ابتدای سال1402 | E8: 0 | F8: 48146929233 | H8: 15167092784 | J8: 21130900704 | L8: 135469769034 | N8: 12064805917 | P8: 78376232100 | R8: 21977465870 | T8: 332333195642 | V8: 0 | W8: 0 | X8: 904031500 | Y8: 0 | Z8: 0 | AA8: 0 | AB8: 332333195642
B9: استهلاک | F9: 6555661694 | H9: 4094310055 | J9: 4370976499 | L9: 29706809126 | N9: 522531359 | P9: 18148605202 | R9: 13484191767 | T9: 76883085702 | V9: 0 | X9: 0 | Z9: 0 | AB9: 76883085702
B10: واگذار شده | D10: 0 | F10: 0 | H10: 0 | J10: 0 | L10: 0 | N10: 0 | P10: 0 | R10: 0 | T10: =F10+H10+J10+L10+N10+P10+R10 -> 0 | V10: 0 | X10: 0 | Z10: 0 | AB10: =T10+V10+X10+Z10 -> 0
B11: سایر نقل و انتقالات و تغییرات | D11: 0 | F11: 0 | H11: 0 | J11: 0 | L11: 0 | N11: 0 | P11: 0 | R11: 0 | T11: 0 | V11: 0 | X11: 0 | Z11: 0 | AB11: =T11+V11+X11+Z11 -> 0
B12: مانده در پایان سال1402 | E12: =SUM(E8:E11) -> 0 | F12: =SUM(F8:F11) -> 54702590927 | H12: =SUM(H8:H11) -> 19261402839 | J12: =SUM(J8:J11) -> 25501877203 | L12: =SUM(L8:L11) -> 165176578160 | N12: =SUM(N8:N11) -> 12587337276 | P12: =SUM(P8:P11) -> 96524837302 | R12: =SUM(R8:R11) -> 35461657637 | T12: =SUM(T8:T11) -> 409216281344 | V12: =SUM(V8:V11) -> 0 | W12: =SUM(W8:W11) -> 0 | X12: =SUM(X8:X11) -> 904031500 | Y12: =SUM(Y8:Y11) -> 0 | Z12: =SUM(Z8:Z11) -> 0 | AA12: =SUM(AA8:AA11) -> 0 | AB12: =SUM(AB8:AB11) -> 409216281344
B13: استهلاک | D13: 0 | F13: 6553770879 | G13: 0 | H13: 3898741718 | J13: 5231771477 | L13: 28051833167 | N13: 461837869 | P13: 13709240286 | R13: 16875684040 | T13: =F13+H13+J13+L13+N13+P13+R13 -> 74782879436 | V13: 0 | X13: 0 | Z13: 0 | AB13: =T13+V13+X13+Z13 -> 74782879436 | AH13: =T13+'13-14'!O16 -> 83087283880
B14: واگذار شده | D14: 0 | F14: 0 | H14: 0 | J14: 0 | L14: 0 | N14: 0 | P14: 0 | R14: 0 | T14: =SUM(D14:R14) -> 0 | V14: 0 | X14: 0 | Z14: 0
B15: مانده در پایان سال 1403 | D15: =SUM(D12:D14) -> 0 | F15: =SUM(F12:F14) -> 61256361806 | H15: =SUM(H12:H14) -> 23160144557 | J15: =SUM(J12:J14) -> 30733648680 | L15: =SUM(L12:L14) -> 193228411327 | N15: =SUM(N12:N14) -> 13049175145 | P15: =SUM(P12:P14) -> 110234077588 | R15: =SUM(R12:R14) -> 52337341677 | T15: =D15+F15+H15+J15+L15+N15+P15+R15 -> 483999160780 | V15: =SUM(V12:V14) -> 0 | X15: =SUM(X12:X14) -> 904031500 | Z15: 0 | AB15: =SUM(AB12:AB14) -> 483999160780
B16: مبلغ دفتری در پایان سال1403 | D16: ='12'!E17-'12-1'!D15 -> 3370015495 | F16: ='12 اصلی'!G17-'12-1'!F15 -> 134597737595 | H16: ='12 اصلی'!I17-'12-1'!H15 -> 35102589129 | J16: ='12 اصلی'!K17-'12-1'!J15 -> 59412691218 | L16: ='12 اصلی'!M17-'12-1'!L15 -> 120205543490 | N16: ='12 اصلی'!O17-'12-1'!N15 -> 372599310 | P16: ='12 اصلی'!Q17-'12-1'!P15 -> 32783568563 | R16: ='12 اصلی'!S17-'12-1'!R15 -> 38020853410 | T16: =D16+F16+H16+J16+L16+N16+P16+R16 -> 423865598210 | V16: 0 | X16: ='12 اصلی'!Y17 -> 15791391800 | Z16: 0 | AB16: =SUM(T16:Z16) -> 439656990010 | AH16: =AB16='وضعيت مالي'!F8 -> TRUE
B17: مبلغ دفتری در پایان سال 1402 | D17: ='12 اصلی'!E12-'12-1'!D12 -> 3370015495 | F17: ='12 اصلی'!G12-'12-1'!F12 -> 141151508474 | H17: ='12 اصلی'!I12-'12-1'!H12 -> 38973930847 | J17: ='12 اصلی'!K12-'12-1'!J12 -> 59261732695 | L17: ='12 اصلی'!M12-'12-1'!L12 -> 143702224107 | N17: ='12 اصلی'!O12-'12-1'!N12 -> 834437179 | P17: ='12 اصلی'!Q12-'12-1'!P12 -> 45045057653 | R17: ='12 اصلی'!S12-'12-1'!R12 -> 36181880877 | T17: =D17+F17+H17+J17+L17+N17+P17+R17 -> 468520787327 | V17: ='12 اصلی'!W12 -> 0 | X17: ='12 اصلی'!Y12 -> 12388796860 | Y17: ='12'!Z13-'12-1'!Y12 -> 0 | Z17: 0 | AB17: =SUM(T17:Z17) -> 480909584187 | AH17: =AB17='وضعيت مالي'!H8 -> TRUE
A28: 16

Sheet 12-2
A1: شرکت داروسازی خوارزمی ( سهامی خاص )
A2: ='12-1'!A2:AC2 -> يادداشتهاي توضيحي صورتهاي مالي
A3: =سودوزيان!A3 -> سال مالی منتهی به 30 اسفند 1403
A5: 12-1- | B5: دارایی های ثابت مشهود تا ارزش 3.998.800 میلیون ریال در مقابل خطرات احتمالی ناشی از حریق،سیل و زلزله از پوشش بیمه ای برخوردار است.
A7: 12-2- | B7: افزایش مبلغ ماشین آلات عمدتا" بابت خرید سایز پارت به مبلغ3.525 میلیون ریال می باشد .
A9: 12-3- | B9: افزایش مبلغ ابزارآلات عمدتا" بابت خريد سنبه وماتریس به مبلغ 18.585 میلیون ریال می باشد.
A12: 12-4- | B12: افزایش مبلغ اثاثیه و منصوبات عمدتا" بابت خریدپرینتر.صندلی.کیس کامپیوتر.فشارسنج.اسکنرویخچال فریزر به ترتيب به مبلغ 360 و225و205و184و170و164 میلیون ریال می باشد
A14: 12-5-افزايش مبلغ لوازم آزمايشگاهي بابت خريد دستگاه هیتراستیرر به مبلغ27 میلیون می باشد
A16: 12-6- افزايش مبلغ تاسيسات عمدتاً بابت خریددستگاه EDI وپمپ شناوربه ترتيب به مبلغ4.150و1.105 ميليون ريال مي باشد
A18: 12-7ساختمان و زمین به مبلغ 48،264 میلیون ریال بابت دریافت تسهیلات در وثیقه بانک صنعت و معدن می باشد
A19: 17

Sheet 12-8
A1: شرکت داروسازی خوارزمی (سهامی خاص)
A2: یادداشتهای توضیحی صورت های مالی
A3: =سودوزيان!A3 -> سال مالی منتهی به 30 اسفند 1403
A5: 12-8- | B5: گردش پیش پرداختهای سرمایه ای به شرح ذیل می باشد
D6: مانده در 1402/12/29 | F6: افزایش | H6: کاهش | J6: مانده در 1403/12/30
B7: شهرداری منطقه 21 | D7: 3535674000 | F7: 0 | H7: 0 | J7: =D7+F7-H7 -> 3535674000
B8: آرسا صنعت مازند | D8: 3360000000 | J8: =D8+F8-H8 -> 3360000000
B9: دستگاه هواساز 1 عدد از کشور آلمان | D9: 2519283360 | J9: =D9+F9-H9 -> 2519283360
B10: شرکت تولیدی و صنعتی نوید | D10: 1091362500 | F10: 1042312500 | H10: 2133675000 | J10: =D10+F10-H10 -> 0
B11: شرکت نیما تهویه آرا | D11: 708445500 | F11: 0 | H11: 0 | J11: =D11+F11-H11 -> 708445500
B12: سامانه ایده پرداز پردیس | D12: 240000000 | F12: 0 | H12: 240000000 | J12: =D12+F12-H12 -> 0
B13: ماشین پرکن-آرگین خچاطوریان | D13: 30000000 | F13: 0 | H13: 30000000 | J13: =D13+F13-H13 -> 0
B14: اندیشه نگار پارس | D14: 0 | F14: 847000000 | H14: 0 | J14: =D14+F14-H14 -> 847000000
B15: شرکت صنعتی شوفاژ کار | D15: 0 | F15: 831457440 | H15: 0 | J15: =D15+F15-H15 -> 831457440
B16: پایا ساخت وتولید میهن | D16: 0 | F16: 3085500000 | H16: 0 | J16: =D16+F16-H16 -> 3085500000
B17: گروه فنی مهندسی پارت دارو الوند | D17: 0 | F17: 4334000000 | H17: 4334000000 | J17: =D17+F17-H17 -> 0
B18: مهندسی مشاور فرآیند سازان مهاب | D18: 0 | F18: 4565000000 | H18: 4565000000 | J18: =D18+F18-H18 -> 0
B19: پارت پمپ | D19: 0 | F19: 1104730000 | H19: 1104730000 | J19: =D19+F19-H19 -> 0
B20: سایر | D20: 904031500 | F20: 0 | J20: =D20+F20-H20 -> 904031500
D21: =SUM(D7:D20) -> 12388796860 | F21: =SUM(F7:F20) -> 15809999940 | H21: =SUM(H7:H19) -> 12407405000 | J21: =SUM(J7:J20) -> 15791391800 | Q21: =D21='12-1'!X17 -> TRUE | S21: =J21='12-1'!X16 -> TRUE
A23: 12-8-1 | B23: عمده پیش پرداخت های سرمایه ای مربوط به شهرداری منطقه 21 و آرسا صنعت مازند و دستگاه هواساز می باشد که به ترتیب بابت ساخت 6000 متر زمین جنوبی -خرید دستگاه کلاو باکس-خرید دستگاه هواساز می باشد.
A33: 18

Sheet 13-14
A1: شرکت داروسازی خوارزمی (سهامی خاص)
A2: =تاريخچه!A2 -> يادداشتهاي توضيحي صورتهاي مالي
A3: =سودوزيان!A3 -> سال مالی منتهی به 30 اسفند 1403
A5: 13- | B5: دارایی های نامشهود
O6: (مبالغ به ریال)
I7: حق امتیاز خدمات عمومی | K7: نرم افزار رایانه ای | M7: علامت تجاری | O7: جمع
B8: :بهای تمام شده
B9: مانده در ابتدای سال 1402 | I9: 3768903919 | K9: 21981130000 | M9: 50000000 | O9: =I9+K9+M9 -> 25800033919
B10: افزایش | I10: 0 | K10: 3573000000 | M10: 0 | O10: =I10+K10+M10 -> 3573000000
B11: مانده در پایان سال 1402 | I11: =SUM(I9:I9) -> 3768903919 | K11: =SUM(K9:K10) -> 25554130000 | M11: 50000000 | O11: =SUM(O9:O10) -> 29373033919
B12: افزایش | I12: 0 | K12: 0 | M12: 0 | O12: =I12+K12+M12 -> 0
B13: مانده در پایان سال 1403 | I13: =SUM(I11:I12) -> 3768903919 | K13: =SUM(K11:K12) -> 25554130000 | M13: =SUM(M11:M12) -> 50000000 | O13: =SUM(I13:M13) -> 29373033919
B14: استهلاک انباشته
B15: مانده در ابتدای سال 1402 | I15: 0 | K15: 9025673333 | M15: 0 | O15: =I15+K15+M15 -> 9025673333
B16: افزایش | I16: 0 | K16: 8304404444 | M16: 0 | O16: =I16+K16+M16 -> 8304404444
B17: مانده در پایان سال 1402 | I17: =I16 -> 0 | K17: =SUM(K15:K16) -> 17330077777 | M17: =M16 -> 0 | O17: =SUM(O15:O16) -> 17330077777
B18: افزایش | I18: 0 | K18: 8224052223 | M18: 0 | O18: =K18 -> 8224052223
B19: مانده در پایان سال 1403 | I19: 0 | K19: =K18+K17 -> 25554130000 | M19: 0 | O19: =O18+O17 -> 25554130000
B20: مبلغ دفتری در پایان سال 1403 | I20: =I13-I17 -> 3768903919 | J20: =J13 -> 0 | K20: 0 | L20: =L13 -> 0 | M20: =M13-M17 -> 50000000 | N20: =N13 -> 0 | O20: =O13-O19 -> 3818903919 | P20: =P13 -> 0 | U20: =O20='وضعيت مالي'!F9 -> TRUE
B21: مبلغ دفتری در پایان سال 1402 | I21: =I13 -> 3768903919 | K21: =K11-K17 -> 8224052223 | M21: =M13 -> 50000000 | O21: =SUM(I21:M21) -> 12042956142
A25: 14- | B25: سرمایه گذاری های بلند مدت:
K26: 1403 | O26: 1402
K27: بهای تمام شده | O27: مبلغ دفتری
K28: ریال | O28: ریال
A29: سرمایه گذاری در سهام شرکت ها | K29: 2245465728 | O29: 2245465728
K30: =SUM(K29) -> 2245465728 | O30: =SUM(O29:O29) -> 2245465728 | U30: =K30-'وضعيت مالي'!F10 -> 0
A32: 14-1- | B32: سرمایه گذاری در سهام شرکت ها به شرح زیر تفکیک می شود :
K33: (مبالغ به ریال)
E34: 1403 | O34: 1402
E35: تعداد سهام | G35: درصد سرمایه گذاری | I35: بهای تمام شده | K35: کاهش ارزش انباشته | M35: مبلغ دفتری | O35: مبلغ دفتری | S35: ارزش بازار
A36: سرمایه گذاری سریع المعامله
A37: (بورسی و فرا بورسی):
A38: فولاد مبارکه اصفهان | E38: 2649827 | G38: 0/09% | I38: =M38 -> 872865728 | K38: 0 | M38: 872865728 | O38: 872865728 | S38: 2912159870
I39: =SUM(I38) -> 872865728 | K39: =SUM(K38) -> 0 | M39: =SUM(M38) -> 872865728 | O39: =SUM(O38) -> 872865728 | S39: =SUM(S38) -> 2912159870
A41: سرمایه گذاری درسهام سایرشرکتها
A42: مجتمع صنایع داروئی | E42: 108000 | G42: 1/4% | I42: =M42 -> 1080000000 | M42: 1080000000 | O42: 1080000000 | S42: 0
A43: تعاونی انجمن داروسازان | E43: 770 | I43: =M43 -> 292600000 | M43: 292600000 | O43: 292600000 | S43: 0
I44: =SUM(I39:I43) -> 2245465728 | K44: 0 | M44: =SUM(M39:M43) -> 2245465728 | O44: =SUM(O39:O43) -> 2245465728 | S44: =SUM(S39:S43) -> 2912159870
A46: 19

Sheet 15
A1: شرکت داروسازی خوارزمی (سهامی خاص)
